Workbook
Name IQ_CH: 110000
Name IQ_CQ: 5000
Name IQ_CY: 10000
Name IQ_DAILY: 500000
Name IQ_FH: 100000
Name IQ_FQ: 500
Name IQ_FY: 1000
Name IQ_LTM: 2000
Name IQ_MONTH: 15000
Name IQ_NTM: 6000
Name IQ_WEEK: 50000
Name IQ_YTD: 3000
Name UPDATE: 'Data Sheet'!$E$1

Sheet DCF>

Sheet WACC
B6: Weighted Average Cost of Capital
B8: All figures are in INR unless stated otherwise.
B10: Peer Comps
G11: Debt/ | H11: Debt/ | I11: Levered | J11: Unlevered
B12: Name | C12: Country | D12: Total Debt | E12: Total Equity | F12: Tax Rate 1 | G12: Equity | H12: Capital | I12: Beta 2 | J12: Beta 3
B14: ='Beta - Comps'!C7 -> Asian Paints | C14: India | D14: ='Beta - Comps'!D7 -> 2290.29 | E14: ='Beta - Comps'!E7 -> 218706.71 | F14: 0.25 | G14: =D14/E14 -> 0.01047197 | H14: =D14/(D14+E14) -> 0.010363444 | I14: 0.8 | J14: =I14/(1+(1-F14)*G14) -> 0.79376578
B15: ='Beta - Comps'!C8 -> Berger Paints | C15: India | D15: ='Beta - Comps'!D8 -> 670.27 | E15: ='Beta - Comps'!E8 -> 64404.03 | F15: 0.25 | G15: =D15/E15 -> 0.010407268 | H15: =D15/(D15+E15) -> 0.010300072 | I15: 0.81 | J15: =I15/(1+(1-F15)*G15) -> 0.80372655
B16: ='Beta - Comps'!C9 -> Kansai Nerolac | C16: India | D16: ='Beta - Comps'!D9 -> 296.39 | E16: ='Beta - Comps'!E9 -> 19589.74 | F16: 0.25 | G16: =D16/E16 -> 0.015129859 | H16: =D16/(D16+E16) -> 0.014904358 | I16: 0.95 | J16: =I16/(1+(1-F16)*G16) -> 0.93934093
B17: ='Beta - Comps'!C10 -> Akzo Nobel | C17: India | D17: ='Beta - Comps'!D10 -> 62.1 | E17: ='Beta - Comps'!E10 -> 14753.7 | F17: 0.25 | G17: =D17/E17 -> 0.0042091136 | H17: =D17/(D17+E17) -> 0.0041914713 | I17: 0.7 | J17: =I17/(1+(1-F17)*G17) -> 0.69779717
B18: ='Beta - Comps'!C11 -> Indigo Paints | C18: India | D18: ='Beta - Comps'!D11 -> 19.69 | E18: ='Beta - Comps'!E11 -> 5363.66 | F18: 0.25 | G18: =D18/E18 -> 0.0036710008 | H18: =D18/(D18+E18) -> 0.0036575738 | I18: 0.7 | J18: =I18/(1+(1-F18)*G18) -> 0.69807802
E20: Average | F20: =AVERAGE(F14:F18) -> 0.25 | G20: =AVERAGE(G14:G18) -> 0.0087778421 | H20: =AVERAGE(H14:H18) -> 0.0086833839 | I20: =AVERAGE(I14:I18) -> 0.792 | J20: =AVERAGE(J14:J18) -> 0.78654169
E21: Median | F21: =MEDIAN(F14:F18) -> 0.25 | G21: =MEDIAN(G14:G18) -> 0.010407268 | H21: =MEDIAN(H14:H18) -> 0.010300072 | I21: =MEDIAN(I14:I18) -> 0.8 | J21: =MEDIAN(J14:J18) -> 0.79376578
B24: Cost of Debt | G24: Cost of Equity
B26: Pre-tax Cost of Debt | E26: =227.02/2290.29 -> 0.099122819 | G26: Risk Free Rate | J26: 0.063
B27: Tax Rate | E27: =F21 -> 0.25 | G27: Equity Risk Premium | J27: =(11.42-J26)/100 -> 0.11357
B28: After Tax Cost of Debt | E28: =E26*(1-E27) -> 0.074342114 | G28: Levered Beta 4 | J28: =J37 -> 0.79898049
G29: Cost of Equity | J29: =J26+(J27*J28) -> 0.15374021
B32: Capital Structure | G32: Levered Beta
D34: Current | E34: Target | G34: Comps Median Unlevered Beta | J34: =J21 -> 0.79376578
B35: Total Debt | C35: =D14 -> 2290.29 | D35: =C35/$C$37 -> 0.010363444 | E35: =H20 -> 0.0086833839 | G35: Target Debt/ Equity | J35: =E39 -> 0.0087594455
B36: Market Capitalization | C36: =E14 -> 218706.71 | D36: =C36/$C$37 -> 0.98963656 | E36: =E37-E35 -> 0.99131662 | G36: Tax Rate | J36: =E27 -> 0.25
B37: Total Capitalization | C37: =SUM(C35:C36) -> 220997 | D37: =C37/$C$37 -> 1 | E37: =D37 -> 1 | G37: Levered Beta | J37: =J34*(1+(1-J36)*J35) -> 0.79898049
B39: Debt / Equity | D39: =D35/D36 -> 0.01047197 | E39: =E35/E36 -> 0.0087594455 | G39: Weighted Average Cost of Capital
B41: 1. Tax Rate considered as Marginal Tax Rate for the country | G41: Cost of Equity | J41: =J29 -> 0.15374021
B42: 2. Levered Beta is based on 5 year monthly data | G42: Equity Weight | J42: =E36 -> 0.99131662
B43: 3. Unlevered Beta = Levered Beta/(1+(1-Tax Rate) x Debt/Equity)
B44: 4. Levered Beta = Unlevered Beta/(1+(1-Tax Rate) x Debt/Equity) | G44: Cost of Debt | J44: =E28 -> 0.074342114
G45: Debt Weight | J45: =E35 -> 0.0086833839
G47: WACC | J47: =(J41*J42)+(J44*J45) -> 0.15305077

Sheet Data>

Sheet Beta - Comps
B6: S.No. | C6: Name | D6: debt | E6: mark cap | F6: Debt / Eq
B7: 1 | C7: Asian Paints | D7: 2290.29 | E7: 218706.71 | F7: =D7/E7 -> 0.01047197
B8: 2 | C8: Berger Paints | D8: 670.27 | E8: 64404.03 | F8: =D8/E8 -> 0.010407268
B9: 3 | C9: Kansai Nerolac | D9: 296.39 | E9: 19589.74 | F9: =D9/E9 -> 0.015129859
B10: 4 | C10: Akzo Nobel | D10: 62.1 | E10: 14753.7 | F10: =D10/E10 -> 0.0042091136
B11: 5 | C11: Indigo Paints | D11: 19.69 | E11: 5363.66 | F11: =D11/E11 -> 0.0036710008

Sheet Intrisic Growth
B6: Calculation of ROIC | G6: ='Raw FS'!J$2 -> 44256 | H6: ='Raw FS'!K$2 -> 44621 | I6: ='Raw FS'!L$2 -> 44986 | J6: ='Raw FS'!M$2 -> 45352 | K6: ='Raw FS'!N$2 -> 45717
B8: Current Assets
B9: ='Raw FS'!B35 -> Inventories | G9: ='Raw FS'!J35 -> 3799 | H9: ='Raw FS'!K35 -> 6153 | I9: ='Raw FS'!L35 -> 6211 | J9: ='Raw FS'!M35 -> 5923 | K9: ='Raw FS'!N35 -> 6719
B10: ='Raw FS'!B36 -> Trade receivables | G10: ='Raw FS'!J36 -> 2602 | H10: ='Raw FS'!K36 -> 3871 | I10: ='Raw FS'!L36 -> 4637 | J10: ='Raw FS'!M36 -> 4889 | K10: ='Raw FS'!N36 -> 4314
B11: ='Raw FS'!B38 -> Loans n Advances | G11: ='Raw FS'!J38 -> 11 | H11: ='Raw FS'!K38 -> 8 | I11: ='Raw FS'!L38 -> 12 | J11: ='Raw FS'!M38 -> 17 | K11: ='Raw FS'!N38 -> 22
B12: ='Raw FS'!B39 -> Other asset items | G12: ='Raw FS'!J39 -> 2555 | H12: ='Raw FS'!K39 -> 2869 | I12: ='Raw FS'!L39 -> 3024 | J12: ='Raw FS'!M39 -> 3555 | K12: ='Raw FS'!N39 -> 3319
B13: Total Current Assets | G13: =SUM(G9:G12) -> 8967 | H13: =SUM(H9:H12) -> 12901 | I13: =SUM(I9:I12) -> 13884 | J13: =SUM(J9:J12) -> 14384 | K13: =SUM(K9:K12) -> 14374
B15: Current Liabilities
B16: ='Raw FS'!B13 -> Trade Payables | G16: ='Raw FS'!J13 -> 3379 | H16: ='Raw FS'!K13 -> 4164 | I16: ='Raw FS'!L13 -> 3635 | J16: ='Raw FS'!M13 -> 3831 | K16: ='Raw FS'!N13 -> 3848
B17: ='Raw FS'!B14 -> Advance from Customers | G17: ='Raw FS'!J14 -> 41 | H17: ='Raw FS'!K14 -> 76 | I17: ='Raw FS'!L14 -> 108 | J17: ='Raw FS'!M14 -> 154 | K17: ='Raw FS'!N14 -> 173
B18: ='Raw FS'!B15 -> Other liability items | G18: ='Raw FS'!J15 -> 2613 | H18: ='Raw FS'!K15 -> 2932 | I18: ='Raw FS'!L15 -> 3657 | J18: ='Raw FS'!M15 -> 4017 | K18: ='Raw FS'!N15 -> 3985
B19: Total Current Liabilities | G19: =SUM(G16:G18) -> 6033 | H19: =SUM(H16:H18) -> 7172 | I19: =SUM(I16:I18) -> 7400 | J19: =SUM(J16:J18) -> 8002 | K19: =SUM(K16:K18) -> 8006
A21: # | B21: Net Working Capital | G21: =G13-G19 -> 2934 | H21: =H13-H19 -> 5729 | I21: =I13-I19 -> 6484 | J21: =J13-J19 -> 6382 | K21: =K13-K19 -> 6368
B23: Non Current Assets
B24: ='Raw FS'!B19 -> Land | G24: ='Raw FS'!J19 -> 644 | H24: ='Raw FS'!K19 -> 644 | I24: ='Raw FS'!L19 -> 804 | J24: ='Raw FS'!M19 -> 1126 | K24: ='Raw FS'!N19 -> 1050
B25: ='Raw FS'!B20 -> Building | G25: ='Raw FS'!J20 -> 2249 | H25: ='Raw FS'!K20 -> 2325 | I25: ='Raw FS'!L20 -> 2883 | J25: ='Raw FS'!M20 -> 3390 | K25: ='Raw FS'!N20 -> 4136
B26: ='Raw FS'!B21 -> Plant Machinery | G26: ='Raw FS'!J21 -> 4340 | H26: ='Raw FS'!K21 -> 4531 | I26: ='Raw FS'!L21 -> 4825 | J26: ='Raw FS'!M21 -> 5422 | K26: ='Raw FS'!N21 -> 7576
B27: ='Raw FS'!B22 -> Equipments | G27: ='Raw FS'!J22 -> 243 | H27: ='Raw FS'!K22 -> 253 | I27: ='Raw FS'!L22 -> 270 | J27: ='Raw FS'!M22 -> 298 | K27: ='Raw FS'!N22 -> 325
B28: ='Raw FS'!B23 -> Furniture n fittings | G28: ='Raw FS'!J23 -> 99 | H28: ='Raw FS'!K23 -> 113 | I28: ='Raw FS'!L23 -> 146 | J28: ='Raw FS'!M23 -> 175 | K28: ='Raw FS'!N23 -> 203
B29: ='Raw FS'!B24 -> Vehicles | G29: ='Raw FS'!J24 -> 38 | H29: ='Raw FS'!K24 -> 32 | I29: ='Raw FS'!L24 -> 36 | J29: ='Raw FS'!M24 -> 40 | K29: ='Raw FS'!N24 -> 39
B30: ='Raw FS'!B25 -> Intangible Assets | G30: ='Raw FS'!J25 -> 476 | H30: ='Raw FS'!K25 -> 345 | I30: ='Raw FS'!L25 -> 422 | J30: ='Raw FS'!M25 -> 850 | K30: ='Raw FS'!N25 -> 827
B31: ='Raw FS'!B26 -> Other fixed assets | G31: ='Raw FS'!J26 -> 302 | H31: ='Raw FS'!K26 -> 294 | I31: ='Raw FS'!L26 -> 289 | J31: ='Raw FS'!M26 -> 321 | K31: ='Raw FS'!N26 -> 328
B33: Gross Block | G33: =SUM(G24:G32) -> 8391 | H33: =SUM(H24:H32) -> 8537 | I33: =SUM(I24:I32) -> 9675 | J33: =SUM(J24:J32) -> 11622 | K33: =SUM(K24:K32) -> 14484
B34: Accumulated Depreciation | G34: =-'Raw FS'!J28 -> -2533 | H34: =-'Raw FS'!K28 -> -3019 | I34: =-'Raw FS'!L28 -> -3814 | J34: =-'Raw FS'!M28 -> -4381 | K34: =-'Raw FS'!N28 -> -4945
A35: # | B35: Net Non Current Assets | G35: =SUM(G33:G34) -> 5858 | H35: =SUM(H33:H34) -> 5518 | I35: =SUM(I33:I34) -> 5861 | J35: =SUM(J33:J34) -> 7241 | K35: =SUM(K33:K34) -> 9539
A37: # | B37: Invested Capital | G37: =G35+G21 -> 8792 | H37: =H35+H21 -> 11247 | I37: =I35+I21 -> 12345 | J37: =J35+J21 -> 13623 | K37: =K35+K21 -> 15907
B38: EBIT | G38: ='Data Sheet'!G28+'Data Sheet'!G27 -> 4395.98 | H38: ='Data Sheet'!H28+'Data Sheet'!H27 -> 4283.13 | I38: ='Data Sheet'!I28+'Data Sheet'!I27 -> 5833.28 | J38: ='Data Sheet'!J28+'Data Sheet'!J27 -> 7552.94 | K38: ='Data Sheet'!K28+'Data Sheet'!K27 -> 5330.09
A40: # | B40: ROIC | G40: =G38/G37 -> 0.49999773 | H40: =H38/H37 -> 0.38082422 | I40: =I38/I37 -> 0.47252167 | J40: =J38/J37 -> 0.5544256 | K40: =K38/K37 -> 0.33507827
A43: # | B43: Calculation of Reinvestment Rate | G43: ='Raw FS'!J$2 -> 44256 | H43: ='Raw FS'!K$2 -> 44621 | I43: ='Raw FS'!L$2 -> 44986 | J43: ='Raw FS'!M$2 -> 45352 | K43: ='Raw FS'!N$2 -> 45717
B45: Net Capex | G45: =-SUM('Raw FS'!J54:J55) -> 254 | H45: =-SUM('Raw FS'!K54:K55) -> 511 | I45: =-SUM('Raw FS'!L54:L55) -> 1420 | J45: =-SUM('Raw FS'!M54:M55) -> 2491 | K45: =-SUM('Raw FS'!N54:N55) -> 1820
B46: Change in Working Capital | H46: =H21-G21 -> 2795 | I46: =I21-H21 -> 755 | J46: =J21-I21 -> -102 | K46: =K21-J21 -> -14
B48: EBIT | G48: =G38 -> 4395.98 | H48: =H38 -> 4283.13 | I48: =I38 -> 5833.28 | J48: =J38 -> 7552.94 | K48: =K38 -> 5330.09
B49: Marginal Tax Rate | G49: 0.25 | H49: 0.25 | I49: 0.25 | J49: 0.25 | K49: 0.25
B50: EBIT(1-T) | G50: =G48*(1-G49) -> 3296.985 | H50: =H48*(1-H49) -> 3212.3475 | I50: =I48*(1-I49) -> 4374.96 | J50: =J48*(1-J49) -> 5664.705 | K50: =K48*(1-K49) -> 3997.5675
B52: Reinvestment | H52: =SUM(H45:H46) -> 3306 | I52: =SUM(I45:I46) -> 2175 | J52: =SUM(J45:J46) -> 2389 | K52: =SUM(K45:K46) -> 1806
B54: Reinvestment Rate | H54: =H52/H50 -> 1.0291539 | I54: =I52/I50 -> 0.4971474 | J54: =J52/J50 -> 0.42173423 | K54: =K52/K50 -> 0.45177474
J56: 4 Year Average | K56: =AVERAGE(H54:K54) -> 0.59995257
J57: 4 Year Median | K57: =MEDIAN(H54:K54) -> 0.47446107
A59: # | B59: Calculation of Growth Rate | G59: ='Raw FS'!J$2 -> 44256 | H59: ='Raw FS'!K$2 -> 44621 | I59: ='Raw FS'!L$2 -> 44986 | J59: ='Raw FS'!M$2 -> 45352 | K59: ='Raw FS'!N$2 -> 45717
B61: Reinvestment Rate | H61: =H54 -> 1.0291539 | I61: =I54 -> 0.4971474 | J61: =J54 -> 0.42173423 | K61: =K54 -> 0.45177474
...

Sheet DCF
B6: Calculation of PV of FCFF | E6: ='Intrisic Growth'!K6 -> 45717 | F6: =E6+365 -> 46082 | G6: =F6+366 -> 46448 | H6: =G6+365 -> 46813 | I6: =H6+365 -> 47178 | J6: =I6+365 -> 47543
B8: EBIT | E8: ='Intrisic Growth'!K38 -> 5330.09 | F8: =E8*(1+$D$18) -> 6579.285 | G8: =F8*(1+$D$18) -> 8121.2496 | H8: =G8*(1+$D$18) -> 10024.599 | I8: =H8*(1+$D$18) -> 12374.03 | J8: =I8*(1+$D$18) -> 15274.089
B9: Tax Rate | E9: 0.25 | F9: =E9 -> 0.25 | G9: =F9 -> 0.25 | H9: =G9 -> 0.25 | I9: =H9 -> 0.25 | J9: =I9 -> 0.25
B10: EBIT(1-T) | E10: =E8*(1-E9) -> 3997.5675 | F10: =F8*(1-F9) -> 4934.4638 | G10: =G8*(1-G9) -> 6090.9372 | H10: =H8*(1-H9) -> 7518.4493 | I10: =I8*(1-I9) -> 9280.5227 | J10: =J8*(1-J9) -> 11455.567
B11: Less: Reinvestment Rate | E11: ='Intrisic Growth'!K61 -> 0.45177474 | F11: =E11+(($J$11-$E$11)/4) -> 0.46168105 | G11: =F11+(($J$11-$E$11)/4) -> 0.47158737 | H11: =G11+(($J$11-$E$11)/4) -> 0.48149368 | I11: =H11+(($J$11-$E$11)/4) -> 0.4914 | J11: 0.4914
B12: Free Cash Flow to Firm (FCFF) | E12: =E10*(1-E11) -> 2191.5675 | F12: =F10*(1-F11) -> 2656.3153 | G12: =G10*(1-G11) -> 3218.5282 | H12: =H10*(1-H11) -> 3898.3635 | I12: =I10*(1-I11) -> 4720.0738 | J12: =J10*(1-J11) -> 5826.3014
B13: Mid Year Convention | F13: 0.5 | G13: =+F13+1 -> 1.5 | H13: =+G13+1 -> 2.5 | I13: =+H13+1 -> 3.5 | J13: =+I13+1 -> 4.5
B14: Discounting Factor | F14: =1/(1+$D$20)^F13 -> 0.93127037 | G14: =1/(1+$D$20)^G13 -> 0.80765773 | H14: =1/(1+$D$20)^H13 -> 0.70045288 | I14: =1/(1+$D$20)^I13 -> 0.60747792 | J14: =1/(1+$D$20)^J13 -> 0.52684403
B16: PV of FCFF | F16: =F12*F14 -> 2473.7478 | G16: =G12*G14 -> 2599.4691 | H16: =H12*H14 -> 2730.6199 | I16: =I12*I14 -> 2867.3406 | J16: =J12*J14 -> 3069.5521
B18: Expected Growth | D18: ='Intrisic Growth'!K67 -> 0.23436659
B19: Terminal Growth | D19: 0.065
B20: WACC | D20: =WACC!J47 -> 0.15305077
B22: Calculation of Terminal Value
B24: FCFF (n+1) | D24: =J12*(1+D18) -> 7191.7918
B25: WACC | D25: =D20 -> 0.15305077
B26: Terminal Growth Rate | D26: =D19 -> 0.065
B28: Terminal Value | D28: =D24/(D25-D26) -> 81677.784
B31: Calculation of Equity Value per Share
B33: PV of FCFF | D33: =SUM(F16:J16) -> 13740.73
B34: PV of Terminal Value | D34: =D28*J14 -> 43031.453
B35: Value of Operating Assets | D35: =SUM(D33:D34) -> 56772.183
B37: Add: Cash | D37: ='Raw FS'!N37 -> 782
B38: Less: Debt | D38: =SUM('Raw FS'!N7:N8) -> 864
B39: Value of Equity | D39: =D35+D37-D38 -> 56690.183
B40: No of Shares | D40: ='Data Sheet'!B6 -> 95.919785
B42: Equity Value per Share | D42: =D39/D40 -> 591.01657
B44: Share price | D44: 2275.6
B45: Discount/Premium | D45: =D44/D42 -> 3.850315

Sheet Data Room>

Sheet Data Sheet
A1: COMPANY NAME | B1: ASIAN PAINTS LTD | E1: =IF(B2<>B3, "A NEW VERSION OF THE WORKSHEET IS AVAILABLE", "")
A2: LATEST VERSION | B2: 2.1 | E2: PLEASE DO NOT MAKE ANY CHANGES TO THIS SHEET
A3: CURRENT VERSION | B3: 2.1
A5: META
A6: Number of shares | B6: =IF(B9>0, B9/B8, 0) -> 95.919785
A7: Face Value | B7: 1
A8: Current Price | B8: 2278
A9: Market Capitalization | B9: 218505.27
A15: PROFIT & LOSS | B15: =B26+B34 -> 3189.81 | K15: =K17-K18-K20-K21-K22-K23-K19 -> 6879.41
A16: Report Date | B16: 42460 | C16: 42825 | D16: 43190 | E16: 43555 | F16: 43921 | G16: 44286 | H16: 44651 | I16: 45016 | J16: 45382 | K16: 45747
A17: Sales | B17: 14271.49 | C17: 15061.99 | D17: 16824.55 | E17: 19240.13 | F17: 20211.25 | G17: 21712.79 | H17: 29101.28 | I17: 34488.59 | J17: 35494.73 | K17: 33905.62
A18: Raw Material Cost | B18: 6569.83 | C18: 7452.6 | D18: 8128.17 | E18: 9974.4 | F18: 9981.99 | G18: 10425.55 | H18: 17123.25 | I18: 18985.53 | J18: 17410.84 | K18: 17504.51
A19: Change in Inventory | B19: -199.33 | C19: 528.6 | D19: -142.13 | E19: 293.26 | F19: 239.15 | G19: 92.45 | H19: 1324.97 | I19: 309.73 | J19: -363.8 | K19: 205
A20: Power and Fuel | B20: 114.48 | C20: 106.02 | D20: 110.3 | E20: 119.63 | F20: 97.79 | G20: 86.05 | H20: 117.23 | I20: 138.29 | J20: 133.25 | K20: 148.58
A21: Other Mfr. Exp | B21: 1535.22 | C21: 1662.75 | D21: 1691.68 | E21: 1862.35 | F21: 1946.12 | G21: 2068.31 | H21: 2880.45 | I21: 2916.2 | J21: 2767.18 | K21: 2687.4
A22: Employee Cost | B22: 994.98 | C22: 1039.89 | D22: 1121.89 | E22: 1242.69 | F22: 1371.27 | G22: 1547.61 | H22: 1794.61 | I22: 2036.41 | J22: 2334.92 | K22: 2605.78
A23: Selling and admin | B23: 3912.3 | C23: 4364.04 | D23: 2254.92 | E23: 2366.87 | F23: 2311.51 | G23: 2245.69 | H23: 2941.98 | I23: 3500.84 | J23: 3811.86 | K23: 3874.94
A24: Other Expenses | B24: -1779.69 | C24: -2028.47 | D24: 171.45 | E24: 202.51 | F24: 584.9 | G24: 576.43 | H24: 765.12 | I24: 961.21 | J24: 1087.9 | K24: 1283.2
A25: Other Income | B25: 213.39 | C25: 337.9 | D25: 336.41 | E25: 273.77 | F25: 355.05 | G25: 331.65 | H25: 295.88 | I25: 431.46 | J25: 820.96 | K25: 350.22
A26: Depreciation | B26: 275.58 | C26: 334.79 | D26: 360.47 | E26: 622.14 | F26: 780.5 | G26: 791.27 | H26: 816.36 | I26: 858.02 | J26: 853 | K26: 1026.34
A27: Interest | B27: 49 | C27: 37.33 | D27: 41.47 | E27: 110.47 | F27: 102.33 | G27: 91.63 | H27: 95.41 | I27: 144.45 | J27: 205.17 | K27: 227.02
... A31: Dividend Amount | B31: 719.4 | C31: 987.98 | D31: 834.5 | E31: 1007.16 | F31: 1151.04 | G31: 1712.17 | H31: 1836.87 | I31: 2460.35 | J31: 3194.14 | K31: 2378.82
A32: Effective Tax Rate | B32: =B29/B28 -> 0.32308281 | C32: =C29/C28 -> 0.31872859 | D32: =D29/D28 -> 0.33167648 | E32: =E29/E28 -> 0.33213151 | F32: =F29/F28 -> 0.23555816 | G32: =G29/G28 -> 0.25499785 | H32: =H29/H28 -> 0.26336766 | I32: =I29/I28 -> 0.26253201 | ... K32: =K29/K28 -> 0.27304348
A34: EBITDA | B34: =+B30+B29+B27+B26 -> 2914.23 | C34: =+C30+C29+C27+C26 -> 3254.84 | D34: =+D30+D29+D27+D26 -> 3481.83 | E34: =+E30+E29+E27+E26 -> 3986.59 | F34: =+F30+F29+F27+F26 -> 4442.85 | G34: =+G30+G29+G27+G26 -> 5119.79 | H34: =+H30+H29+H27+H26 -> 5045.25 | I34: =+I30+I29+I27+I26 -> 6602.42 | ... K34: =+K30+K29+K27+K26 -> 6313.95
A40: Quarters
A41: Report Date | B41: 44926 | C41: 45016 | D41: 45107 | E41: 45199 | F41: 45291 | G41: 45382 | H41: 45473 | I41: 45565 | J41: 45657 | K41: 45747
A42: Sales | B42: 8636.74 | C42: 8787.34 | D42: 9182.31 | E42: 8478.57 | F42: 9103.09 | G42: 8730.76 | H42: 8969.73 | I42: 8027.54 | J42: 8549.44 | K42: 8358.91
A43: Expenses | B43: 7025.31 | C43: 6922.58 | D43: 7061.02 | E43: 6762.34 | F43: 7047 | G43: 7039.39 | H43: 7275.96 | I43: 6788.03 | J43: 6912.71 | K43: 6922.71
A44: Other Income | B44: 122.21 | C44: 104.17 | D44: 227.74 | E44: 194.33 | F44: 186.46 | G44: 212.43 | H44: 192.93 | I44: 24.53 | J44: 192.82 | K44: -60.06
A45: Depreciation | B45: 214.05 | C45: 220.17 | D45: 198.32 | E45: 208.72 | F45: 220.35 | G45: 225.61 | H45: 227.7 | I45: 241.99 | J45: 255.55 | K45: 301.1
A46: Interest | B46: 41.39 | C46: 38.91 | D46: 45.75 | E46: 50.9 | F46: 54.42 | G46: 54.1 | H46: 55.38 | I46: 63.01 | J46: 55.84 | K46: 52.79
A47: Profit before tax | B47: 1478.2 | C47: 1709.85 | D47: 2104.96 | E47: 1650.94 | F47: 1967.78 | G47: 1624.09 | H47: 1603.62 | I47: 959.04 | J47: 1518.16 | K47: 1022.25
A48: Tax | B48: 381.14 | C48: 451.44 | D48: 530.12 | E48: 418.55 | F48: 492.62 | G48: 348.79 | H48: 416.83 | I48: 265.38 | J48: 389.73 | K48: 321.42
A49: Net profit | B49: 1072.67 | C49: 1234.14 | D49: 1550.37 | E49: 1205.42 | F49: 1447.72 | G49: 1256.72 | H49: 1169.98 | I49: 694.64 | J49: 1110.48 | K49: 692.13
A50: Operating Profit | B50: 1611.43 | C50: 1864.76 | D50: 2121.29 | E50: 1716.23 | F50: 2056.09 | G50: 1691.37 | H50: 1693.77 | I50: 1239.51 | J50: 1636.73 | K50: 1436.2
A51: EBITDA | B51: =B49+B48+B46+B45 -> 1709.25 | C51: =C49+C48+C46+C45 -> 1944.66 | D51: =D49+D48+D46+D45 -> 2324.56 | E51: =E49+E48+E46+E45 -> 1883.59 | F51: =F49+F48+F46+F45 -> 2215.11 | G51: =G49+G48+G46+G45 -> 1885.22 | H51: =H49+H48+H46+H45 -> 1869.89 | I51: =I49+I48+I46+I45 -> 1265.02 | ... K51: =K49+K48+K46+K45 -> 1367.44
A55: BALANCE SHEET
A56: Report Date | B56: 42460 | C56: 42825 | D56: 43190 | E56: 43555 | F56: 43921 | G56: 44286 | H56: 44651 | I56: 45016 | J56: 45382 | K56: 45747
A57: Equity Share Capital | B57: 95.92 | C57: 95.92 | D57: 95.92 | E57: 95.92 | F57: 95.92 | G57: 95.92 | H57: 95.92 | I57: 95.92 | J57: 95.92 | K57: 95.92
A58: Reserves | B58: 6428.9 | C58: 7507.97 | D58: 8314.31 | E58: 9374.63 | F58: 10034.24 | G58: 12710.37 | H58: 13715.64 | I58: 15896.31 | J58: 18632.38 | K58: 19303.89
...

Sheet Raw FS
B2: Particulars | C2: 41699 | D2: 42064 | E2: 42430 | F2: 42795 | G2: 43160 | H2: 43525 | I2: 43891 | J2: 44256 | K2: 44621 | L2: 44986 | M2: 45352 | N2: 45717
B4: Equity Capital | C4: 96 | D4: 96 | E4: 96 | F4: 96 | G4: 96 | H4: 96 | I4: 96 | J4: 96 | K4: 96 | L4: 96 | M4: 96 | N4: 96
B5: Reserves | C5: 3943 | D5: 4646 | E5: 6429 | F5: 7508 | G5: 8314 | H5: 9375 | I5: 10034 | J5: 12710 | K5: 13716 | L5: 15896 | M5: 18632 | N5: 19304
B6: Borrowings -
B7: Long term Borrowings | C7: 41 | D7: 78 | E7: 73 | F7: 41 | G7: 28 | H7: 19 | I7: 19 | J7: 15 | K7: 45 | L7: 76 | M7: 54 | N7: 260
B8: Short term Borrowings | C8: 199 | D8: 332 | E8: 231 | F8: 504 | G8: 492 | H8: 597 | I8: 321 | J8: 334 | K8: 731 | L8: 896 | M8: 1053 | N8: 604
B9: Lease Liabilities | C9: 0 | D9: 0 | E9: 0 | F9: 0 | G9: 0 | H9: 693 | I9: 764 | J9: 745 | K9: 811 | L9: 960 | M9: 1367 | N9: 1427
B10: Other Borrowings | C10: 9 | D10: 8 | E10: 20 | F10: 15 | G10: 13 | H10: 11 | I10: 15 | J10: 0 | K10: 0 | L10: 0 | M10: 0 | N10: 0
B11: Other Liabilities -
B12: Non controlling int | C12: 246 | D12: 264 | E12: 384 | F12: 375 | G12: 328 | H12: 361 | I12: 404 | J12: 423 | K12: 388 | L12: 454 | M12: 695 | N12: 659
B13: Trade Payables | C13: 1746 | D13: 1549 | E13: 1565 | F13: 1923 | G13: 2160 | H13: 2394 | I13: 2137 | J13: 3379 | K13: 4164 | L13: 3635 | M13: 3831 | N13: 3848
B14: Advance from Customers | C14: 0 | D14: 5 | E14: 12 | F14: 17 | G14: 16 | H14: 13 | I14: 29 | J14: 41 | K14: 76 | L14: 108 | M14: 154 | N14: 173
B15: Other liability items | C15: 1795 | D15: 1937 | E15: 1750 | F15: 1925 | G15: 2316 | H15: 2690 | I15: 2320 | J15: 2613 | K15: 2932 | L15: 3657 | M15: 4017 | N15: 3985
B16: Total Liabilities | C16: =SUM(C4:C15) -> 8075 | D16: =SUM(D4:D15) -> 8915 | E16: =SUM(E4:E15) -> 10560 | F16: =SUM(F4:F15) -> 12404 | G16: =SUM(G4:G15) -> 13763 | H16: =SUM(H4:H15) -> 16249 | I16: =SUM(I4:I15) -> 16139 | J16: =SUM(J4:J15) -> 20356 | ... N16: =SUM(N4:N15) -> 30356
B18: Fixed Assets -
B19: Land | C19: 247 | D19: 251 | E19: 429 | F19: 408 | G19: 586 | H19: 605 | I19: 640 | J19: 644 | K19: 644 | L19: 804 | M19: 1126 | N19: 1050
B20: Building | C20: 931 | D20: 962 | E20: 923 | F20: 931 | G20: 957 | H20: 2402 | I20: 2257 | J20: 2249 | K20: 2325 | L20: 2883 | M20: 3390 | N20: 4136
B21: Plant Machinery | C21: 2054 | D21: 2132 | E21: 1793 | F21: 1980 | G21: 2157 | H21: 4006 | I21: 4208 | J21: 4340 | K21: 4531 | L21: 4825 | M21: 5422 | N21: 7576
B22: Equipments | C22: 155 | D22: 171 | E22: 97 | F22: 119 | G22: 200 | H22: 221 | I22: 241 | J22: 243 | K22: 253 | L22: 270 | M22: 298 | N22: 325
B23: Furniture n fittings | C23: 71 | D23: 83 | E23: 49 | F23: 59 | G23: 72 | H23: 88 | I23: 94 | J23: 99 | K23: 113 | L23: 146 | M23: 175 | N23: 203
B24: Vehicles | C24: 14 | D24: 18 | E24: 11 | F24: 14 | G24: 27 | H24: 47 | I24: 43 | J24: 38 | K24: 32 | L24: 36 | M24: 40 | N24: 39
B25: Intangible Assets | C25: 203 | D25: 351 | E25: 339 | F25: 276 | G25: 468 | H25: 512 | I25: 505 | J25: 476 | K25: 345 | L25: 422 | M25: 850 | N25: 827
B26: Other fixed assets | C26: 128 | D26: 145 | E26: 103 | F26: 128 | G26: 238 | H26: 261 | I26: 293 | J26: 302 | K26: 294 | L26: 289 | M26: 321 | N26: 328
B27: Gross Block | C27: =SUM(C19:C26) -> 3803 | D27: =SUM(D19:D26) -> 4113 | E27: =SUM(E19:E26) -> 3744 | F27: =SUM(F19:F26) -> 3915 | G27: =SUM(G19:G26) -> 4705 | H27: =SUM(H19:H26) -> 8142 | I27: =SUM(I19:I26) -> 8281 | J27: =SUM(J19:J26) -> 8391 | ... N27: =SUM(N19:N26) -> 14484
B28: Accumulated Depreciation | C28: 1223 | D28: 1438 | E28: 275 | F28: 610 | G28: 973 | H28: 1592 | I28: 2010 | J28: 2533 | K28: 3019 | L28: 3814 | M28: 4381 | N28: 4945
B29: Net Block | C29: =C27-C28 -> 2580 | D29: =D27-D28 -> 2675 | E29: =E27-E28 -> 3469 | F29: =F27-F28 -> 3305 | G29: =G27-G28 -> 3732 | H29: =H27-H28 -> 6550 | I29: =I27-I28 -> 6271 | J29: =J27-J28 -> 5858 | ... N29: =N27-N28 -> 9539
B31: CWIP | C31: 43 | D31: 617 | E31: 59 | F31: 72 | G31: 196 | H31: 107 | I31: 258 | J31: 1405 | K31: 210 | L31: 140 | M31: 183 | N31: 426
B32: Investments | C32: 429 | D32: 355 | E32: 296 | F32: 1424 | G32: 1588 | H32: 2712 | I32: 2652 | J32: 2141 | K32: 2569 | L32: 2019 | M32: 4737 | N32: 3248
B34: Other Assets -
B35: Inventories | C35: 2070 | D35: 2259 | E35: 1998 | F35: 2627 | G35: 2658 | H35: 3150 | I35: 3390 | J35: 3799 | K35: 6153 | L35: 6211 | M35: 5923 | N35: 6719
B36: Trade receivables | C36: 1110 | D36: 1182 | E36: 1187 | F36: 1447 | G36: 1731 | H36: 1907 | I36: 1795 | J36: 2602 | K36: 3871 | L36: 4637 | M36: 4889 | N36: 4314
B37: Cash Equivalents | C37: 229 | D37: 204 | E37: 424 | F37: 801 | G37: 405 | H37: 445 | I37: 783 | J37: 611 | K37: 864 | L37: 844 | M37: 1084 | N37: 782
B38: Loans n Advances | C38: 7 | D38: 8 | E38: 9 | F38: 14 | G38: 13 | H38: 16 | I38: 12 | J38: 11 | K38: 8 | L38: 12 | M38: 17 | N38: 22
B39: Other asset items | C39: 603 | D39: 817 | E39: 705 | F39: 1303 | G39: 1678 | H39: 1456 | I39: 1727 | J39: 2555 | K39: 2869 | L39: 3024 | M39: 3555 | N39: 3319
B40: Total Assets | C40: 8075 | D40: 8914 | E40: 10559 | F40: 12405 | G40: 13763 | H40: 16249 | I40: 16138 | J40: 20355 | K40: 22958 | L40: 25779 | M40: 29901 | N40: 30355
C44: 41699 | D44: 42064 | E44: 42430 | F44: 42795 | G44: 43160 | H44: 43525 | I44: 43891 | J44: 44256 | K44: 44621 | L44: 44986 | M44: 45352 | N44: 45717
B45: Cash from Operating Activity - | C45: 1402 | D45: 1188 | E45: 2243 | F45: 1527 | G45: 2113 | H45: 2470 | I45: 3038 | J45: 3683 | K45: 986 | L45: 4193 | M45: 6104 | N45: 4424
B46: Profit from operations | C46: 2051 | D46: 2271 | E46: 2848 | F46: 3056 | G46: 3274 | H46: 3861 | I46: 4380 | J46: 4970 | K46: 4957 | L46: 6460 | M46: 7929 | N46: 6390
B47: Receivables | C47: -254 | D47: -155 | E47: -146 | F47: -475 | G47: -483 | H47: -205 | I47: 160 | J47: -849 | K47: -1326 | L47: -834 | M47: -362 | N47: 282
B48: Inventory | C48: -231 | D48: -144 | E48: 202 | F48: -629 | G48: -39 | H48: -492 | I48: -251 | J48: -409 | K48: -2354 | L48: -56 | M48: 315 | N48: -805
...
