Workbook
Name UPDATE: 'Data Sheet'!$E$1

Sheet Data Sheet
A1: COMPANY NAME | B1: MAHINDRA & MAHINDRA LTD | E1: =IF(B2<>B3, "A NEW VERSION OF THE WORKSHEET IS AVAILABLE", "")
A2: LATEST VERSION | B2: 2.1 | E2: PLEASE DO NOT MAKE ANY CHANGES TO THIS SHEET
A3: CURRENT VERSION | B3: 2.1
A5: META
A6: Number of shares | B6: =IF(B9>0, B9/B8, 0) -> 124.35288
A7: Face Value | B7: 5
A8: Current Price | B8: 3090.7
A9: Market Capitalization | B9: 384337.46
A15: PROFIT & LOSS
A16: Report Date | B16: 42460 | C16: 42825 | D16: 43190 | E16: 43555 | F16: 43921 | G16: 44286 | H16: 44651 | I16: 45016 | J16: 45382 | K16: 45747
A17: Sales | B17: 75841.42 | C17: 83773.05 | D17: 92093.95 | E17: 104720.68 | F17: 75381.93 | G17: 74277.78 | H17: 90170.57 | I17: 121268.55 | J17: 139078.27 | K17: 159210.82
A18: Raw Material Cost | B18: 45584.35 | C18: 50655.2 | D18: 53457.29 | E18: 61881.19 | F18: 37595.3 | G18: 38271.2 | H18: 52664.85 | I18: 76019.87 | J18: 85070.07 | K18: 95754.9
A19: Change in Inventory | B19: 458.51 | C19: 13.83 | D19: -83.33 | E19: 1730.48 | F19: -826.62 | G19: -135.59 | H19: 861.66 | I19: 2032.31 | J19: 1455.32 | K19: 12.18
A20: Power and Fuel | B20: 639.97 | C20: 657.06 | D20: 733.9 | E20: 817.11 | F20: 530.92 | G20: 429.56 | H20: 541.27 | I20: 830.48 | J20: 752.73
A21: Other Mfr. Exp | B21: 2618.7 | C21: 3255.3 | D21: 3590.26 | E21: 4253 | F21: 3277.79 | G21: 2523.4 | H21: 3124.27 | I21: 3838.42 | J21: 3791.75
A22: Employee Cost | B22: 7689.4 | C22: 8910.63 | D22: 10004.62 | E22: 11242.08 | F22: 8214.82 | G22: 7813.26 | H22: 8386.74 | I22: 9677.95 | J22: 10624.33 | K22: 11126.17
A23: Selling and admin | B23: 5758.86 | C23: 6253.64 | D23: 7591.15 | E23: 9658.98 | F23: 6316.52 | G23: 4628.75 | H23: 5977.67 | I23: 7681.87 | J23: 9832.2
A24: Other Expenses | B24: 3926.21 | C24: 3320.22 | D24: 3407.3 | E24: 3392.29 | F24: 8462.21 | G24: 8989 | H24: 5654.58 | I24: 4966.98 | J24: 5570.58 | K24: 21823.74
A25: Other Income | B25: 1398.83 | C25: 2076.61 | D25: 4366.41 | E25: 2676.45 | F25: 884.69 | G25: 1151.51 | H25: 3204.47 | I25: 3961.45 | J25: 3297.85 | K25: 3718.47
A26: Depreciation | B26: 2441.65 | C26: 2812.72 | D26: 3279.9 | E26: 3990.77 | F26: 3366.68 | G26: 3378.11 | H26: 3507.5 | I26: 4356.81 | J26: 4723.78 | K26: 6073.65
A27: Interest | B27: 3367.59 | C27: 3648.46 | D27: 3987.09 | E27: 5021.35 | F27: 6021.15 | G27: 6102.22 | H27: 5018.05 | I27: 5829.7 | J27: 7488.21 | K27: 9083.39
A28: Profit before tax | B28: 5672.03 | C28: 6350.26 | D28: 10325.52 | E28: 8870.84 | F28: 1654.61 | G28: 3158.2 | H28: 9361.77 | I28: 14060.23 | J28: 15977.79 | K28: 19079.62
A29: Tax | B29: 2117.53 | C29: 2299.73 | D29: 2367.73 | E29: 2853.99 | F29: 1975.61 | G29: 1645.81 | H29: 2108.76 | I29: 2685.75 | J29: 3707.97 | K29: 5006.45
A30: Net profit | B30: 3148.43 | C30: 3698.04 | D30: 7510.39 | E30: 5315.46 | F30: 127.04 | G30: 1812.49 | H30: 6577.32 | I30: 10281.5 | J30: 11268.64 | K30: 12929.1
A31: Dividend Amount | B31: 648.96 | C31: 807.43 | D31: 814.7 | E31: 924.73 | F31: 260.51 | G31: 971.51 | H31: 1284.5 | I31: 1809.66 | J31: 2352.14 | K31: 2824.24
A40: Quarters
A41: Report Date | B41: 44926 | C41: 45016 | D41: 45107 | E41: 45199 | F41: 45291 | G41: 45382 | H41: 45473 | I41: 45565 | J41: 45657 | K41: 45747
A42: Sales | B42: 30621.28 | C42: 32455.65 | D42: 33891.63 | E42: 34435.52 | F42: 35299.39 | G42: 35451.73 | H42: 37217.72 | I42: 37923.74 | J42: 41470.05 | K42: 42599.31
A43: Expenses | B43: 25367.56 | C43: 26797.92 | D43: 27642.4 | E43: 28705.94 | F43: 29075.41 | G43: 28847.82 | H43: 29974.6 | I43: 30790.34 | J43: 33239.32 | K43: 34688.37
A44: Other Income | B44: 1183.71 | C44: 661.74 | D44: 1065 | E44: 811.95 | F44: 755.69 | G44: 750.44 | H44: 733.21 | I44: 1125.57 | J44: 718.59 | K44: 1141.1
A45: Depreciation | B45: 1110.16 | C45: 1194.4 | D45: 1127.5 | E45: 1138.64 | F45: 1122.59 | G45: 1335.05 | H45: 1247.77 | I45: 1301.99 | J45: 1495.17 | K45: 2028.72
A46: Interest | B46: 1595.56 | C46: 1633.56 | D46: 1718.84 | E46: 1835.19 | F46: 1944.88 | G46: 1989.3 | H46: 2107.69 | I46: 2217.02 | J46: 2362.16 | K46: 2396.52
A47: Profit before tax | B47: 3731.71 | C47: 3491.51 | D47: 4467.89 | E47: 3567.7 | F47: 3912.2 | G47: 4030 | H47: 4620.87 | I47: 4739.96 | J47: 5091.99 | K47: 4626.8
A48: Tax | B48: 737.68 | C48: 493.14 | D48: 784.02 | E48: 1083.73 | F48: 935.16 | G48: 905.06 | H48: 1075.09 | I48: 1378.9 | J48: 1467.51 | K48: 1084.95
A49: Net profit | B49: 2676.56 | C49: 2636.67 | D49: 3508.41 | E49: 2347.75 | F49: 2658.4 | G49: 2754.08 | H49: 3282.63 | I49: 3170.72 | J49: 3180.58 | K49: 3295.17
A50: Operating Profit | B50: 5253.72 | C50: 5657.73 | D50: 6249.23 | E50: 5729.58 | F50: 6223.98 | G50: 6603.91 | H50: 7243.12 | I50: 7133.4 | J50: 8230.73 | K50: 7910.94
A55: BALANCE SHEET
A56: Report Date | B56: 42460 | C56: 42825 | D56: 43190 | E56: 43555 | F56: 43921 | G56: 44286 | H56: 44651 | I56: 45016 | J56: 45382 | K56: 45747
A57: Equity Share Capital | B57: 270.4 | C57: 310.55 | D57: 543.13 | E57: 543.96 | F57: 554.28 | G57: 555.15 | H57: 556.06 | I57: 556.82 | J57: 557.38 | K57: 558.15
A58: Reserves | B58: 26222.25 | C58: 29467.1 | D58: 36232.06 | E58: 39439.45 | F58: 39415.03 | G58: 41026.77 | H58: 46566.58 | I58: 55808.97 | J58: 65633.17 | K58: 76480.71
...

Sheet Cash Flow Data
B1: 42430 | C1: 42795 | D1: 43160 | E1: 43525 | F1: 43891 | G1: 44256 | H1: 44621 | I1: 44986 | J1: 45352 | K1: 45717
A2: Cash from Operating Activity - | B2: 2385 | C2: 183 | D2: 682 | E2: -4347 | F2: -1457 | G2: 17909 | H2: 9248 | I2: -7074 | J2: -5630 | K2: 3176
A3: Profit from operations | B3: 7595 | C3: 7911 | D3: 10159 | E3: 11112 | F3: 7774 | G3: 7588 | H3: 10515 | I3: 15642 | J3: 17541 | K3: 22050
A4: Receivables | B4: 177 | C4: -8609 | D4: -11918 | E4: -13712 | F4: -1516 | G4: 4896 | H4: -2506 | I4: -21702 | J4: -21777 | K4: -3782
A5: Inventory | B5: -1113 | C5: 241 | D5: -256 | E5: -2276 | F5: 1316 | G5: 226 | H5: -2173 | I5: -5252 | J5: -1753 | K5: -1646
A6: Payables | B6: 1939 | C6: 2645 | D6: 5361 | E6: 3466 | F6: -6775 | G6: 7049 | H6: 4972 | I6: 7013 | J6: 4354 | K6: 8485 | M6: =SUM(B3,B9,B10) -> 2384
A7: Loans Advances | B7: 0 | C7: 0 | D7: 0 | E7: 0 | F7: 0 | G7: 0 | H7: 0 | I7: 0 | J7: 0 | K7: 0
A8: Other WC items | B8: -4241 | C8: 0 | D8: 0 | E8: 0 | F8: 0 | G8: 0 | H8: 0 | I8: 0 | J8: 0 | K8: -17170
A9: Working capital changes | B9: -3238 | C9: -5724 | D9: -6813 | E9: -12522 | F9: -6974 | G9: 12171 | H9: 293 | I9: -19941 | J9: -19175 | K9: -14113
A10: Direct taxes | B10: -1973 | C10: -2005 | D10: -2664 | E10: -2937 | F10: -2257 | G10: -1850 | H10: -1560 | I10: -2775 | J10: -3996 | K10: -4761
A11: Cash from Investing Activity - | B11: -5506 | C11: -5875 | D11: -5467 | E11: -7174 | F11: -6870 | G11: -19686 | H11: -3252 | I11: -8866 | J11: -5615 | K11: -18626
A12: Fixed assets purchased | B12: -4172 | C12: -5026 | D12: -5906 | E12: -7340 | F12: -6896 | G12: -5989 | H12: -6040 | I12: -6305 | J12: -9946 | K12: -10392
A13: Fixed assets sold | B13: 59 | C13: 63 | D13: 115 | E13: 142 | F13: 102 | G13: 1364 | H13: 120 | I13: 138 | J13: 273 | K13: 583
A14: Investments purchased | B14: -87898 | C14: -132173 | D14: -155159 | E14: -196474 | F14: -198568 | G14: -120055 | H14: -65421 | I14: -50165 | J14: -49927 | K14: -90595
A15: Investments sold | B15: 86436 | C15: 130940 | D15: 154631 | E15: 195898 | F15: 198132 | G15: 111749 | H15: 65127 | I15: 46269 | J15: 50919 | K15: 85634
A16: Interest received | B16: 311 | C16: 346 | D16: 254 | E16: 314 | F16: 372 | G16: 431 | H16: 420 | I16: 464 | J16: 703 | K16: 884
A17: Dividends received | B17: 208 | C17: 409 | D17: 316 | E17: 466 | F17: 722 | G17: 577 | H17: 1247 | I17: 1397 | J17: 1213 | K17: 1374
A18: Investment in group cos | B18: -147 | C18: -647 | D18: -704 | E18: -319 | F18: -418 | G18: -359 | H18: -222 | I18: -62 | J18: -249 | K18: -29
... A32: Net Cash Flow | B32: -154 | C32: 416 | D32: 1529 | E32: 1672 | F32: -1394 | G32: -1370 | H32: 113 | I32: 6 | J32: 1037 | K32: 384

Sheet FS Analysis
B2: ="Historical Financial Statement - "&'Data Sheet'!B1:C1&"(In Crores)" -> Historical Financial Statement - MAHINDRA & MAHINDRA LTD(In Crores)
B3: Years | C3: ='Data Sheet'!B16 -> 42460 | D3: ='Data Sheet'!C16 -> 42825 | E3: ='Data Sheet'!D16 -> 43190 | F3: ='Data Sheet'!E16 -> 43555 | G3: ='Data Sheet'!F16 -> 43921 | H3: ='Data Sheet'!G16 -> 44286 | I3: ='Data Sheet'!H16 -> 44651 | J3: ='Data Sheet'!I16 -> 45016 | ... L3: ='Data Sheet'!K16 -> 45747
A4: # | B4: Income Statement
B5: Sales | C5: =IFERROR('Data Sheet'!B17,0) -> 75841.42 | D5: =IFERROR('Data Sheet'!C17,0) -> 83773.05 | E5: =IFERROR('Data Sheet'!D17,0) -> 92093.95 | F5: =IFERROR('Data Sheet'!E17,0) -> 104720.68 | G5: =IFERROR('Data Sheet'!F17,0) -> 75381.93 | H5: =IFERROR('Data Sheet'!G17,0) -> 74277.78 | I5: =IFERROR('Data Sheet'!H17,0) -> 90170.57 | J5: =IFERROR('Data Sheet'!I17,0) -> 121268.55 | ... L5: =IFERROR('Data Sheet'!K17,0) -> 159210.82
B6: Sales Growth | C6: - | D6: =IFERROR(D5/C5-1,0) -> 0.10458177 | E6: =IFERROR(E5/D5-1,0) -> 0.099326693 | F6: =IFERROR(F5/E5-1,0) -> 0.13710705 | G6: =IFERROR(G5/F5-1,0) -> -0.28016195 | H6: =IFERROR(H5/G5-1,0) -> -0.01464741 | I6: =IFERROR(I5/H5-1,0) -> 0.21396426 | J6: =IFERROR(J5/I5-1,0) -> 0.34487949 | K6: =IFERROR(K5/J5-1,0) -> 0.14686182 | L6: =IFERROR(L5/K5-1,0) -> 0.14475698
B8: COGS | C8: =IFERROR(SUM('Data Sheet'!B18,'Data Sheet'!B20,'Data Sheet'!B22,'Data Sheet'!B21)-'Data Sheet'!B19,0) -> 56073.91 | D8: =IFERROR(SUM('Data Sheet'!C18,'Data Sheet'!C20,'Data Sheet'!C22,'Data Sheet'!C21)-'Data Sheet'!C19,0) -> 63464.36 | E8: =IFERROR(SUM('Data Sheet'!D18,'Data Sheet'!D20,'Data Sheet'!D22,'Data Sheet'!D21)-'Data Sheet'!D19,0) -> 67869.4 | F8: =IFERROR(SUM('Data Sheet'!E18,'Data Sheet'!E20,'Data Sheet'!E22,'Data Sheet'!E21)-'Data Sheet'!E19,0) -> 76462.9 | G8: =IFERROR(SUM('Data Sheet'!F18,'Data Sheet'!F20,'Data Sheet'!F22,'Data Sheet'!F21)-'Data Sheet'!F19,0) -> 50445.45 | H8: =IFERROR(SUM('Data Sheet'!G18,'Data Sheet'!G20,'Data Sheet'!G22,'Data Sheet'!G21)-'Data Sheet'!G19,0) -> 49173.01 | I8: =IFERROR(SUM('Data Sheet'!H18,'Data Sheet'!H20,'Data Sheet'!H22,'Data Sheet'!H21)-'Data Sheet'!H19,0) -> 63855.47 | J8: =IFERROR(SUM('Data Sheet'!I18,'Data Sheet'!I20,'Data Sheet'!I22,'Data Sheet'!I21)-'Data Sheet'!I19,0) -> 88334.41 | ... L8: =IFERROR(SUM('Data Sheet'!K18,'Data Sheet'!K20,'Data Sheet'!K22,'Data Sheet'!K21)-'Data Sheet'!K19,0) -> 106868.89
B9: COGS % Sales | C9: =IFERROR(C8/C5,0) -> 0.73935733 | D9: =IFERROR(D8/D5,0) -> 0.7575749 | E9: =IFERROR(E8/E5,0) -> 0.73695829 | F9: =IFERROR(F8/F5,0) -> 0.73016046 | G9: =IFERROR(G8/G5,0) -> 0.66919818 | H9: =IFERROR(H8/H5,0) -> 0.66201507 | I9: =IFERROR(I8/I5,0) -> 0.7081631 | J9: =IFERROR(J8/J5,0) -> 0.72841978 | ... L9: =IFERROR(L8/L5,0) -> 0.67124138
B11: Gross Profit | C11: =IFERROR(C5-C8,0) -> 19767.51 | D11: =IFERROR(D5-D8,0) -> 20308.69 | E11: =IFERROR(E5-E8,0) -> 24224.55 | F11: =IFERROR(F5-F8,0) -> 28257.78 | G11: =IFERROR(G5-G8,0) -> 24936.48 | H11: =IFERROR(H5-H8,0) -> 25104.77 | I11: =IFERROR(I5-I8,0) -> 26315.1 | J11: =IFERROR(J5-J8,0) -> 32934.14 | ... L11: =IFERROR(L5-L8,0) -> 52341.93
B12: Gross Margins | C12: =IFERROR(C11/C5,0) -> 0.26064267 | D12: =IFERROR(D11/D5,0) -> 0.2424251 | E12: =IFERROR(E11/E5,0) -> 0.26304171 | F12: =IFERROR(F11/F5,0) -> 0.26983954 | G12: =IFERROR(G11/G5,0) -> 0.33080182 | H12: =IFERROR(H11/H5,0) -> 0.33798493 | I12: =IFERROR(I11/I5,0) -> 0.2918369 | J12: =IFERROR(J11/J5,0) -> 0.27158022 | ... L12: =IFERROR(L11/L5,0) -> 0.32875862
B14: Selling & General Expenses | C14: =IFERROR(SUM('Data Sheet'!B23:B24)-'Data Sheet'!B25,0) -> 8286.24 | D14: =IFERROR(SUM('Data Sheet'!C23:C24)-'Data Sheet'!C25,0) -> 7497.25 | E14: =IFERROR(SUM('Data Sheet'!D23:D24)-'Data Sheet'!D25,0) -> 6632.04 | F14: =IFERROR(SUM('Data Sheet'!E23:E24)-'Data Sheet'!E25,0) -> 10374.82 | G14: =IFERROR(SUM('Data Sheet'!F23:F24)-'Data Sheet'!F25,0) -> 13894.04 | H14: =IFERROR(SUM('Data Sheet'!G23:G24)-'Data Sheet'!G25,0) -> 12466.24 | I14: =IFERROR(SUM('Data Sheet'!H23:H24)-'Data Sheet'!H25,0) -> 8427.78 | J14: =IFERROR(SUM('Data Sheet'!I23:I24)-'Data Sheet'!I25,0) -> 8687.4 | ... L14: =IFERROR(SUM('Data Sheet'!K23:K24)-'Data Sheet'!K25,0) -> 18105.27
B15: S&G Exp % Sales | C15: =IFERROR(C14/C5,0) -> 0.10925745 | D15: =IFERROR(D14/D5,0) -> 0.089494772 | E15: =IFERROR(E14/E5,0) -> 0.072013851 | F15: =IFERROR(F14/F5,0) -> 0.099071358 | G15: =IFERROR(G14/G5,0) -> 0.18431526 | H15: =IFERROR(H14/H5,0) -> 0.1678327 | I15: =IFERROR(I14/I5,0) -> 0.093464863 | J15: =IFERROR(J14/J5,0) -> 0.0716377 | ... L15: =IFERROR(L14/L5,0) -> 0.11371884
B17: EBITDA | C17: =IFERROR(C11-C14,0) -> 11481.27 | D17: =IFERROR(D11-D14,0) -> 12811.44 | E17: =IFERROR(E11-E14,0) -> 17592.51 | F17: =IFERROR(F11-F14,0) -> 17882.96 | G17: =IFERROR(G11-G14,0) -> 11042.44 | H17: =IFERROR(H11-H14,0) -> 12638.53 | I17: =IFERROR(I11-I14,0) -> 17887.32 | J17: =IFERROR(J11-J14,0) -> 24246.74 | ... L17: =IFERROR(L11-L14,0) -> 34236.66
B18: EBITDA Margins | C18: =IFERROR(C17/C5,0) -> 0.15138522 | D18: =IFERROR(D17/D5,0) -> 0.15293033 | E18: =IFERROR(E17/E5,0) -> 0.19102786 | F18: =IFERROR(F17/F5,0) -> 0.17076818 | G18: =IFERROR(G17/G5,0) -> 0.14648657 | H18: =IFERROR(H17/H5,0) -> 0.17015223 | I18: =IFERROR(I17/I5,0) -> 0.19837204 | J18: =IFERROR(J17/J5,0) -> 0.19994252 | ... L18: =IFERROR(L17/L5,0) -> 0.21503978
B20: Interest | C20: =IFERROR('Data Sheet'!B27,0) -> 3367.59 | D20: =IFERROR('Data Sheet'!C27,0) -> 3648.46 | E20: =IFERROR('Data Sheet'!D27,0) -> 3987.09 | F20: =IFERROR('Data Sheet'!E27,0) -> 5021.35 | G20: =IFERROR('Data Sheet'!F27,0) -> 6021.15 | H20: =IFERROR('Data Sheet'!G27,0) -> 6102.22 | I20: =IFERROR('Data Sheet'!H27,0) -> 5018.05 | J20: =IFERROR('Data Sheet'!I27,0) -> 5829.7 | ... L20: =IFERROR('Data Sheet'!K27,0) -> 9083.39
B21: Interest % Sales | C21: =IFERROR(C20/C5,0) -> 0.044403045 | D21: =IFERROR(D20/D5,0) -> 0.043551715 | E21: =IFERROR(E20/E5,0) -> 0.043293723 | F21: =IFERROR(F20/F5,0) -> 0.047949937 | G21: =IFERROR(G20/G5,0) -> 0.079875243 | H21: =IFERROR(H20/H5,0) -> 0.082154044 | I21: =IFERROR(I20/I5,0) -> 0.055650641 | J21: =IFERROR(J20/J5,0) -> 0.048072645 | ... L21: =IFERROR(L20/L5,0) -> 0.057052592
B23: Depreciation | C23: =IFERROR('Data Sheet'!B26,0) -> 2441.65 | D23: =IFERROR('Data Sheet'!C26,0) -> 2812.72 | E23: =IFERROR('Data Sheet'!D26,0) -> 3279.9 | F23: =IFERROR('Data Sheet'!E26,0) -> 3990.77 | G23: =IFERROR('Data Sheet'!F26,0) -> 3366.68 | H23: =IFERROR('Data Sheet'!G26,0) -> 3378.11 | I23: =IFERROR('Data Sheet'!H26,0) -> 3507.5 | J23: =IFERROR('Data Sheet'!I26,0) -> 4356.81 | ... L23: =IFERROR('Data Sheet'!K26,0) -> 6073.65
B24: Depreciation%Sales | C24: =IFERROR(C23/C5,0) -> 0.032194149 | D24: =IFERROR(D23/D5,0) -> 0.033575476 | E24: =IFERROR(E23/E5,0) -> 0.035614717 | F24: =IFERROR(F23/F5,0) -> 0.03810871 | G24: =IFERROR(G23/G5,0) -> 0.044661632 | H24: =IFERROR(H23/H5,0) -> 0.045479415 | I24: =IFERROR(I23/I5,0) -> 0.038898501 | J24: =IFERROR(J23/J5,0) -> 0.035926957 | ... L24: =IFERROR(L23/L5,0) -> 0.038148475
B26: Earnings Before Tax | C26: =IFERROR(C17-SUM(C20,C23),0) -> 5672.03 | D26: =IFERROR(D17-SUM(D20,D23),0) -> 6350.26 | E26: =IFERROR(E17-SUM(E20,E23),0) -> 10325.52 | F26: =IFERROR(F17-SUM(F20,F23),0) -> 8870.84 | G26: =IFERROR(G17-SUM(G20,G23),0) -> 1654.61 | H26: =IFERROR(H17-SUM(H20,H23),0) -> 3158.2 | I26: =IFERROR(I17-SUM(I20,I23),0) -> 9361.77 | J26: =IFERROR(J17-SUM(J20,J23),0) -> 14060.23 | ... L26: =IFERROR(L17-SUM(L20,L23),0) -> 19079.62
B27: EBT % Sales | C27: =IFERROR(C26/C5,0) -> 0.074788025 | D27: =IFERROR(D26/D5,0) -> 0.075803137 | E27: =IFERROR(E26/E5,0) -> 0.11211942 | F27: =IFERROR(F26/F5,0) -> 0.084709534 | G27: =IFERROR(G26/G5,0) -> 0.02194969 | H27: =IFERROR(H26/H5,0) -> 0.042518772 | I27: =IFERROR(I26/I5,0) -> 0.1038229 | J27: =IFERROR(J26/J5,0) -> 0.11594292 | ... L27: =IFERROR(L26/L5,0) -> 0.11983871
B29: Tax | C29: =IFERROR('Data Sheet'!B29,0) -> 2117.53 | D29: =IFERROR('Data Sheet'!C29,0) -> 2299.73 | E29: =IFERROR('Data Sheet'!D29,0) -> 2367.73 | F29: =IFERROR('Data Sheet'!E29,0) -> 2853.99 | G29: =IFERROR('Data Sheet'!F29,0) -> 1975.61 | H29: =IFERROR('Data Sheet'!G29,0) -> 1645.81 | I29: =IFERROR('Data Sheet'!H29,0) -> 2108.76 | J29: =IFERROR('Data Sheet'!I29,0) -> 2685.75 | ... L29: =IFERROR('Data Sheet'!K29,0) -> 5006.45
B30: Effective Tax Rate | C30: =IFERROR(C29/C26,0) -> 0.37332842 | D30: =IFERROR(D29/D26,0) -> 0.36214738 | E30: =IFERROR(E29/E26,0) -> 0.22930855 | F30: =IFERROR(F29/F26,0) -> 0.32172714 | G30: =IFERROR(G29/G26,0) -> 1.1940034 | H30: =IFERROR(H29/H26,0) -> 0.52112279 | I30: =IFERROR(I29/I26,0) -> 0.22525228 | J30: =IFERROR(J29/J26,0) -> 0.1910175 | ... L30: =IFERROR(L29/L26,0) -> 0.26239778
B32: Net Profit | C32: =IFERROR('Data Sheet'!B30,0) -> 3148.43 | D32: =IFERROR('Data Sheet'!C30,0) -> 3698.04 | E32: =IFERROR('Data Sheet'!D30,0) -> 7510.39 | F32: =IFERROR('Data Sheet'!E30,0) -> 5315.46 | G32: =IFERROR('Data Sheet'!F30,0) -> 127.04 | H32: =IFERROR('Data Sheet'!G30,0) -> 1812.49 | I32: =IFERROR('Data Sheet'!H30,0) -> 6577.32 | J32: =IFERROR('Data Sheet'!I30,0) -> 10281.5 | ... L32: =IFERROR('Data Sheet'!K30,0) -> 12929.1
B33: Net Margins | C33: =IFERROR(C32/C5,0) -> 0.041513331 | D33: =IFERROR(D32/D5,0) -> 0.044143552 | E33: =IFERROR(E32/E5,0) -> 0.081551394 | F33: =IFERROR(F32/F5,0) -> 0.050758456 | G33: =IFERROR(G32/G5,0) -> 0.0016852845 | H33: =IFERROR(H32/H5,0) -> 0.02440151 | I33: =IFERROR(I32/I5,0) -> 0.07294309 | J33: =IFERROR(J32/J5,0) -> 0.084782905 | ... L33: =IFERROR(L32/L5,0) -> 0.08120742
B35: No of Equity Shares | C35: =IFERROR('Data Sheet'!B93,0) -> 124.22 | D35: =IFERROR('Data Sheet'!C93,0) -> 124.22 | E35: =IFERROR('Data Sheet'!D93,0) -> 124.32 | F35: =IFERROR('Data Sheet'!E93,0) -> 124.32 | G35: =IFERROR('Data Sheet'!F93,0) -> 124.32 | H35: =IFERROR('Data Sheet'!G93,0) -> 124.32 | I35: =IFERROR('Data Sheet'!H93,0) -> 124.32 | J35: =IFERROR('Data Sheet'!I93,0) -> 124.35 | ... L35: =IFERROR('Data Sheet'!K93,0) -> 124.35
B37: Earnings per Share | C37: =IFERROR(C32/C35,0) -> 25.345597 | D37: =IFERROR(D32/D35,0) -> 29.770085 | E37: =IFERROR(E32/E35,0) -> 60.41176 | F37: =IFERROR(F32/F35,0) -> 42.756274 | G37: =IFERROR(G32/G35,0) -> 1.021879 | H37: =IFERROR(H32/H35,0) -> 14.579231 | I37: =IFERROR(I32/I35,0) -> 52.906371 | J37: =IFERROR(J32/J35,0) -> 82.681946 | ... L37: =IFERROR(L32/L35,0) -> 103.97346
B38: EPS Growth % | C38: - | D38: =IFERROR(D37/C37-1,0) -> 0.17456637 | E38: =IFERROR(E37/D37-1,0) -> 1.0292774 | F38: =IFERROR(F37/E37-1,0) -> -0.29225247 | G38: =IFERROR(G37/F37-1,0) -> -0.9760999 | H38: =IFERROR(H37/G37-1,0) -> 13.267081 | I38: =IFERROR(I37/H37-1,0) -> 2.6288862 | J38: =IFERROR(J37/I37-1,0) -> 0.56279754 | K38: =IFERROR(K37/J37-1,0) -> 0.096011282 | L38: =IFERROR(L37/K37-1,0) -> 0.1473523
B40: Dividend per Share | C40: =IFERROR('Data Sheet'!B31/'FS Analysis'!C35,0) -> 5.2242795 | D40: =IFERROR('Data Sheet'!C31/'FS Analysis'!D35,0) -> 6.5 | E40: =IFERROR('Data Sheet'!D31/'FS Analysis'!E35,0) -> 6.5532497 | F40: =IFERROR('Data Sheet'!E31/'FS Analysis'!F35,0) -> 7.4383044 | G40: =IFERROR('Data Sheet'!F31/'FS Analysis'!G35,0) -> 2.0954794 | H40: =IFERROR('Data Sheet'!G31/'FS Analysis'!H35,0) -> 7.8145914 | I40: =IFERROR('Data Sheet'!H31/'FS Analysis'!I35,0) -> 10.332207 | J40: =IFERROR('Data Sheet'!I31/'FS Analysis'!J35,0) -> 14.552955 | ... L40: =IFERROR('Data Sheet'!K31/'FS Analysis'!L35,0) -> 22.712023
B41: Dividend payout ratio | C41: =IFERROR(C40/C37,0) -> 0.20612178 | D41: =IFERROR(D40/D37,0) -> 0.21833999 | E41: =IFERROR(E40/E37,0) -> 0.10847639 | F41: =IFERROR(F40/F37,0) -> 0.17396989 | G41: =IFERROR(G40/G37,0) -> 2.050614 | H41: =IFERROR(H40/H37,0) -> 0.53600847 | I41: =IFERROR(I40/I37,0) -> 0.19529231 | J41: =IFERROR(J40/J37,0) -> 0.17601128 | ... L41: =IFERROR(L40/L37,0) -> 0.21844057
B43: Retained Earnings | C43: =IFERROR(IF(C37>C40,1-C41,0),0) -> 0.79387822 | D43: =IFERROR(IF(D37>D40,1-D41,0),0) -> 0.78166001 | E43: =IFERROR(IF(E37>E40,1-E41,0),0) -> 0.89152361 | F43: =IFERROR(IF(F37>F40,1-F41,0),0) -> 0.82603011 | G43: =IFERROR(IF(G37>G40,1-G41,0),0) -> 0 | H43: =IFERROR(IF(H37>H40,1-H41,0),0) -> 0.46399153 | I43: =IFERROR(IF(I37>I40,1-I41,0),0) -> 0.80470769 | J43: =IFERROR(IF(J37>J40,1-J41,0),0) -> 0.82398872 | ... L43: =IFERROR(IF(L37>L40,1-L41,0),0) -> 0.78155943
A45: # | B45: Balance Sheet
B46: =IFERROR('Data Sheet'!A57,0) -> Equity Share Capital | C46: =IFERROR('Data Sheet'!B57,0) -> 270.4 | D46: =IFERROR('Data Sheet'!C57,0) -> 310.55 | E46: =IFERROR('Data Sheet'!D57,0) -> 543.13 | F46: =IFERROR('Data Sheet'!E57,0) -> 543.96 | G46: =IFERROR('Data Sheet'!F57,0) -> 554.28 | H46: =IFERROR('Data Sheet'!G57,0) -> 555.15 | I46: =IFERROR('Data Sheet'!H57,0) -> 556.06 | ... L46: =IFERROR('Data Sheet'!K57,0) -> 558.15
B47: =IFERROR('Data Sheet'!A58,0) -> Reserves | C47: =IFERROR('Data Sheet'!B58,0) -> 26222.25 | D47: =IFERROR('Data Sheet'!C58,0) -> 29467.1 | E47: =IFERROR('Data Sheet'!D58,0) -> 36232.06 | F47: =IFERROR('Data Sheet'!E58,0) -> 39439.45 | G47: =IFERROR('Data Sheet'!F58,0) -> 39415.03 | H47: =IFERROR('Data Sheet'!G58,0) -> 41026.77 | I47: =IFERROR('Data Sheet'!H58,0) -> 46566.58 | ... L47: =IFERROR('Data Sheet'!K58,0) -> 76480.71
B48: =IFERROR('Data Sheet'!A59,0) -> Borrowings | C48: =IFERROR('Data Sheet'!B59,0) -> 41552.93 | D48: =IFERROR('Data Sheet'!C59,0) -> 48761.91 | E48: =IFERROR('Data Sheet'!D59,0) -> 55897.92 | F48: =IFERROR('Data Sheet'!E59,0) -> 70848.3 | G48: =IFERROR('Data Sheet'!F59,0) -> 82092.28 | H48: =IFERROR('Data Sheet'!G59,0) -> 80624.83 | I48: =IFERROR('Data Sheet'!H59,0) -> 77605.21 | ... L48: =IFERROR('Data Sheet'!K59,0) -> 124949.31
B49: =IFERROR('Data Sheet'!A60,0) -> Other Liabilities | C49: =IFERROR('Data Sheet'!B60,0) -> 31806.24 | D49: =IFERROR('Data Sheet'!C60,0) -> 35295.92 | E49: =IFERROR('Data Sheet'!D60,0) -> 43696.2 | F49: =IFERROR('Data Sheet'!E60,0) -> 51056.95 | G49: =IFERROR('Data Sheet'!F60,0) -> 43654.54 | H49: =IFERROR('Data Sheet'!G60,0) -> 42761.58 | I49: =IFERROR('Data Sheet'!H60,0) -> 47660.64 | ... L49: =IFERROR('Data Sheet'!K60,0) -> 75598.1
B50: Total Liabilties | C50: =IFERROR('Data Sheet'!B61,0) -> 99851.82 | D50: =IFERROR('Data Sheet'!C61,0) -> 113835.48 | E50: =IFERROR('Data Sheet'!D61,0) -> 136369.31 | F50: =IFERROR('Data Sheet'!E61,0) -> 161888.66 | G50: =IFERROR('Data Sheet'!F61,0) -> 165716.13 | H50: =IFERROR('Data Sheet'!G61,0) -> 164968.33 | I50: =IFERROR('Data Sheet'!H61,0) -> 172388.49 | J50: =IFERROR('Data Sheet'!I61,0) -> 204283.13 | ... L50: =IFERROR('Data Sheet'!K61,0) -> 277586.27
B52: =IFERROR('Data Sheet'!A62,0) -> Net Block | C52: =IFERROR('Data Sheet'!B62,0) -> 20584.71 | D52: =IFERROR('Data Sheet'!C62,0) -> 20989.01 | E52: =IFERROR('Data Sheet'!D62,0) -> 26181.9 | F52: =IFERROR('Data Sheet'!E62,0) -> 28982.74 | G52: =IFERROR('Data Sheet'!F62,0) -> 29689.27 | H52: =IFERROR('Data Sheet'!G62,0) -> 21379.68 | I52: =IFERROR('Data Sheet'!H62,0) -> 26018.49 | ... L52: =IFERROR('Data Sheet'!K62,0) -> 39281.44
B53: =IFERROR('Data Sheet'!A63,0) -> Capital Work in Progress | C53: =IFERROR('Data Sheet'!B63,0) -> 2371.35 | D53: =IFERROR('Data Sheet'!C63,0) -> 4278.94 | E53: =IFERROR('Data Sheet'!D63,0) -> 4269.47 | F53: =IFERROR('Data Sheet'!E63,0) -> 4759.84 | G53: =IFERROR('Data Sheet'!F63,0) -> 6856.48 | H53: =IFERROR('Data Sheet'!G63,0) -> 7872.61 | I53: =IFERROR('Data Sheet'!H63,0) -> 6702.81 | ... L53: =IFERROR('Data Sheet'!K63,0) -> 3652.56
B54: =IFERROR('Data Sheet'!A64,0) -> Investments | C54: =IFERROR('Data Sheet'!B64,0) -> 11602.58 | D54: =IFERROR('Data Sheet'!C64,0) -> 14662.44 | E54: =IFERROR('Data Sheet'!D64,0) -> 16017.61 | F54: =IFERROR('Data Sheet'!E64,0) -> 18268.1 | G54: =IFERROR('Data Sheet'!F64,0) -> 19210.34 | H54: =IFERROR('Data Sheet'!G64,0) -> 28777.66 | I54: =IFERROR('Data Sheet'!H64,0) -> 30060.43 | ... L54: =IFERROR('Data Sheet'!K64,0) -> 41308.57
B55: =IFERROR('Data Sheet'!A65,0) -> Other Assets | C55: =IFERROR('Data Sheet'!B65-SUM('Data Sheet'!B67:B69),0) -> 45831.91 | D55: =IFERROR('Data Sheet'!C65-SUM('Data Sheet'!C67:C69),0) -> 53165.79 | E55: =IFERROR('Data Sheet'!D65-SUM('Data Sheet'!D67:D69),0) -> 65527.34 | F55: =IFERROR('Data Sheet'!E65-SUM('Data Sheet'!E67:E69),0) -> 80265.02 | G55: =IFERROR('Data Sheet'!F65-SUM('Data Sheet'!F67:F69),0) -> 84009 | H55: =IFERROR('Data Sheet'!G65-SUM('Data Sheet'!G67:G69),0) -> 78463.22 | I55: =IFERROR('Data Sheet'!H65-SUM('Data Sheet'!H67:H69),0) -> 80519.38 | J55: =IFERROR('Data Sheet'!I65-SUM('Data Sheet'!I67:I69),0) -> 102745.73 | ... L55: =IFERROR('Data Sheet'!K65-SUM('Data Sheet'!K67:K69),0) -> 144118.23
B56: Total Non-Current Assets | C56: =IFERROR(SUM(C52:C55),0) -> 80390.55 | D56: =IFERROR(SUM(D52:D55),0) -> 93096.18 | E56: =IFERROR(SUM(E52:E55),0) -> 111996.32 | F56: =IFERROR(SUM(F52:F55),0) -> 132275.7 | G56: =IFERROR(SUM(G52:G55),0) -> 139765.09 | H56: =IFERROR(SUM(H52:H55),0) -> 136493.17 | I56: =IFERROR(SUM(I52:I55),0) -> 143301.11 | J56: =IFERROR(SUM(J52:J55),0) -> 169126.71 | ... L56: =IFERROR(SUM(L52:L55),0) -> 228360.8
...

Sheet Ratio Analysis
B2: ="Ratio Analysis of - "&'Data Sheet'!B1 -> Ratio Analysis of - MAHINDRA & MAHINDRA LTD
B3: Years | C3: ='FS Analysis'!C3 -> 42460 | D3: ='FS Analysis'!D3 -> 42825 | E3: ='FS Analysis'!E3 -> 43190 | F3: ='FS Analysis'!F3 -> 43555 | G3: ='FS Analysis'!G3 -> 43921 | H3: ='FS Analysis'!H3 -> 44286 | I3: ='FS Analysis'!I3 -> 44651 | J3: ='FS Analysis'!J3 -> 45016 | ... L3: ='FS Analysis'!L3 -> 45747 | M3: Trend | N3: Mean | O3: Median
B5: SalesGrowth | D5: =IFERROR('FS Analysis'!D6,0) -> 0.10458177 | E5: =IFERROR('FS Analysis'!E6,0) -> 0.099326693 | F5: =IFERROR('FS Analysis'!F6,0) -> 0.13710705 | G5: =IFERROR('FS Analysis'!G6,0) -> -0.28016195 | H5: =IFERROR('FS Analysis'!H6,0) -> -0.01464741 | I5: =IFERROR('FS Analysis'!I6,0) -> 0.21396426 | J5: =IFERROR('FS Analysis'!J6,0) -> 0.34487949 | K5: =IFERROR('FS Analysis'!K6,0) -> 0.14686182 | L5: =IFERROR('FS Analysis'!L6,0) -> 0.14475698 | N5: =IFERROR(AVERAGE(C5:L5),0) -> 0.099629855 | O5: =IFERROR(MEDIAN(C5:L5),0) -> 0.13710705
B6: EBITDA Growth | D6: =IFERROR('FS Analysis'!D17/'FS Analysis'!C17-1,0) -> 0.11585565 | E6: =IFERROR('FS Analysis'!E17/'FS Analysis'!D17-1,0) -> 0.37318756 | F6: =IFERROR('FS Analysis'!F17/'FS Analysis'!E17-1,0) -> 0.016509867 | G6: =IFERROR('FS Analysis'!G17/'FS Analysis'!F17-1,0) -> -0.38251609 | H6: =IFERROR('FS Analysis'!H17/'FS Analysis'!G17-1,0) -> 0.14454142 | I6: =IFERROR('FS Analysis'!I17/'FS Analysis'!H17-1,0) -> 0.41530067 | J6: =IFERROR('FS Analysis'!J17/'FS Analysis'!I17-1,0) -> 0.35552671 | K6: =IFERROR('FS Analysis'!K17/'FS Analysis'!J17-1,0) -> 0.16262145 | L6: =IFERROR('FS Analysis'!L17/'FS Analysis'!K17-1,0) -> 0.21450611 | N6: =IFERROR(AVERAGE(C6:L6),0) -> 0.15728148 | O6: =IFERROR(MEDIAN(C6:L6),0) -> 0.16262145
B7: EBIT Growth | D7: =IFERROR(('FS Analysis'!D17-'FS Analysis'!D23)/('FS Analysis'!C17-'FS Analysis'!C23)-1,0) -> 0.10609959 | E7: =IFERROR(('FS Analysis'!E17-'FS Analysis'!E23)/('FS Analysis'!D17-'FS Analysis'!D23)-1,0) -> 0.43144422 | F7: =IFERROR(('FS Analysis'!F17-'FS Analysis'!F23)/('FS Analysis'!E17-'FS Analysis'!E23)-1,0) -> -0.029374097 | G7: =IFERROR(('FS Analysis'!G17-'FS Analysis'!G23)/('FS Analysis'!F17-'FS Analysis'!F23)-1,0) -> -0.4474766 | H7: =IFERROR(('FS Analysis'!H17-'FS Analysis'!H23)/('FS Analysis'!G17-'FS Analysis'!G23)-1,0) -> 0.20644992 | I7: =IFERROR(('FS Analysis'!I17-'FS Analysis'!I23)/('FS Analysis'!H17-'FS Analysis'!H23)-1,0) -> 0.5528259 | J7: =IFERROR(('FS Analysis'!J17-'FS Analysis'!J23)/('FS Analysis'!I17-'FS Analysis'!I23)-1,0) -> 0.38318352 | K7: =IFERROR(('FS Analysis'!K17-'FS Analysis'!K23)/('FS Analysis'!J17-'FS Analysis'!J23)-1,0) -> 0.17979299 | L7: =IFERROR(('FS Analysis'!L17-'FS Analysis'!L23)/('FS Analysis'!K17-'FS Analysis'!K23)-1,0) -> 0.20016236 | N7: =IFERROR(AVERAGE(C7:L7),0) -> 0.17590087 | O7: =IFERROR(MEDIAN(C7:L7),0) -> 0.20016236
B8: Net Profit Growth | D8: =IFERROR('FS Analysis'!D32/'FS Analysis'!C32-1,0) -> 0.17456637 | E8: =IFERROR('FS Analysis'!E32/'FS Analysis'!D32-1,0) -> 1.030911 | F8: =IFERROR('FS Analysis'!F32/'FS Analysis'!E32-1,0) -> -0.29225247 | G8: =IFERROR('FS Analysis'!G32/'FS Analysis'!F32-1,0) -> -0.9760999 | H8: =IFERROR('FS Analysis'!H32/'FS Analysis'!G32-1,0) -> 13.267081 | I8: =IFERROR('FS Analysis'!I32/'FS Analysis'!H32-1,0) -> 2.6288862 | J8: =IFERROR('FS Analysis'!J32/'FS Analysis'!I32-1,0) -> 0.56317467 | K8: =IFERROR('FS Analysis'!K32/'FS Analysis'!J32-1,0) -> 0.096011282 | L8: =IFERROR('FS Analysis'!L32/'FS Analysis'!K32-1,0) -> 0.1473523 | N8: =IFERROR(AVERAGE(C8:L8),0) -> 1.8488479 | O8: =IFERROR(MEDIAN(C8:L8),0) -> 0.17456637
B9: Dividend Growth | D9: =IFERROR('FS Analysis'!D40/'FS Analysis'!C40-1,0) -> 0.24419071 | E9: =IFERROR('FS Analysis'!E40/'FS Analysis'!D40-1,0) -> 0.0081922582 | F9: =IFERROR('FS Analysis'!F40/'FS Analysis'!E40-1,0) -> 0.13505585 | G9: =IFERROR('FS Analysis'!G40/'FS Analysis'!F40-1,0) -> -0.71828534 | H9: =IFERROR('FS Analysis'!H40/'FS Analysis'!G40-1,0) -> 2.7292618 | I9: =IFERROR('FS Analysis'!I40/'FS Analysis'!H40-1,0) -> 0.32216858 | J9: =IFERROR('FS Analysis'!J40/'FS Analysis'!I40-1,0) -> 0.40850402 | K9: =IFERROR('FS Analysis'!K40/'FS Analysis'!J40-1,0) -> 0.29976902 | L9: =IFERROR('FS Analysis'!L40/'FS Analysis'!K40-1,0) -> 0.20071084 | N9: =IFERROR(AVERAGE(C9:L9),0) -> 0.40328531 | O9: =IFERROR(MEDIAN(C9:L9),0) -> 0.24419071
B11: Gross Margin | C11: =IFERROR('FS Analysis'!C12,0) -> 0.26064267 | D11: =IFERROR('FS Analysis'!D12,0) -> 0.2424251 | E11: =IFERROR('FS Analysis'!E12,0) -> 0.26304171 | F11: =IFERROR('FS Analysis'!F12,0) -> 0.26983954 | G11: =IFERROR('FS Analysis'!G12,0) -> 0.33080182 | H11: =IFERROR('FS Analysis'!H12,0) -> 0.33798493 | I11: =IFERROR('FS Analysis'!I12,0) -> 0.2918369 | J11: =IFERROR('FS Analysis'!J12,0) -> 0.27158022 | ... L11: =IFERROR('FS Analysis'!L12,0) -> 0.32875862 | N11: =IFERROR(AVERAGE(C11:L11),0) -> 0.28866384 | O11: =IFERROR(MEDIAN(C11:L11),0) -> 0.28065354
B12: EBITDA Margin | C12: =IFERROR('FS Analysis'!C18,0) -> 0.15138522 | D12: =IFERROR('FS Analysis'!D18,0) -> 0.15293033 | E12: =IFERROR('FS Analysis'!E18,0) -> 0.19102786 | F12: =IFERROR('FS Analysis'!F18,0) -> 0.17076818 | G12: =IFERROR('FS Analysis'!G18,0) -> 0.14648657 | H12: =IFERROR('FS Analysis'!H18,0) -> 0.17015223 | I12: =IFERROR('FS Analysis'!I18,0) -> 0.19837204 | J12: =IFERROR('FS Analysis'!J18,0) -> 0.19994252 | ... L12: =IFERROR('FS Analysis'!L18,0) -> 0.21503978 | N12: =IFERROR(AVERAGE(C12:L12),0) -> 0.17987948 | O12: =IFERROR(MEDIAN(C12:L12),0) -> 0.18089802
B13: EBIT Margin | C13: =IFERROR(('FS Analysis'!C17-'FS Analysis'!C23)/'FS Analysis'!C5,0) -> 0.11919107 | D13: =IFERROR(('FS Analysis'!D17-'FS Analysis'!D23)/'FS Analysis'!D5,0) -> 0.11935485 | E13: =IFERROR(('FS Analysis'!E17-'FS Analysis'!E23)/'FS Analysis'!E5,0) -> 0.15541314 | F13: =IFERROR(('FS Analysis'!F17-'FS Analysis'!F23)/'FS Analysis'!F5,0) -> 0.13265947 | G13: =IFERROR(('FS Analysis'!G17-'FS Analysis'!G23)/'FS Analysis'!G5,0) -> 0.10182493 | H13: =IFERROR(('FS Analysis'!H17-'FS Analysis'!H23)/'FS Analysis'!H5,0) -> 0.12467282 | I13: =IFERROR(('FS Analysis'!I17-'FS Analysis'!I23)/'FS Analysis'!I5,0) -> 0.15947354 | J13: =IFERROR(('FS Analysis'!J17-'FS Analysis'!J23)/'FS Analysis'!J5,0) -> 0.16401557 | ... L13: =IFERROR(('FS Analysis'!L17-'FS Analysis'!L23)/'FS Analysis'!L5,0) -> 0.17689131 | N13: =IFERROR(AVERAGE(C13:L13),0) -> 0.14222218 | O13: =IFERROR(MEDIAN(C13:L13),0) -> 0.14403631
B14: EBT Margin | C14: =IFERROR('FS Analysis'!C27,0) -> 0.074788025 | D14: =IFERROR('FS Analysis'!D27,0) -> 0.075803137 | E14: =IFERROR('FS Analysis'!E27,0) -> 0.11211942 | F14: =IFERROR('FS Analysis'!F27,0) -> 0.084709534 | G14: =IFERROR('FS Analysis'!G27,0) -> 0.02194969 | H14: =IFERROR('FS Analysis'!H27,0) -> 0.042518772 | I14: =IFERROR('FS Analysis'!I27,0) -> 0.1038229 | J14: =IFERROR('FS Analysis'!J27,0) -> 0.11594292 | ... L14: =IFERROR('FS Analysis'!L27,0) -> 0.11983871 | N14: =IFERROR(AVERAGE(C14:L14),0) -> 0.086637655 | O14: =IFERROR(MEDIAN(C14:L14),0) -> 0.094266217
B15: Net Profit Margin | C15: =IFERROR('FS Analysis'!C33,0) -> 0.041513331 | D15: =IFERROR('FS Analysis'!D33,0) -> 0.044143552 | E15: =IFERROR('FS Analysis'!E33,0) -> 0.081551394 | F15: =IFERROR('FS Analysis'!F33,0) -> 0.050758456 | G15: =IFERROR('FS Analysis'!G33,0) -> 0.0016852845 | H15: =IFERROR('FS Analysis'!H33,0) -> 0.02440151 | I15: =IFERROR('FS Analysis'!I33,0) -> 0.07294309 | J15: =IFERROR('FS Analysis'!J33,0) -> 0.084782905 | ... L15: =IFERROR('FS Analysis'!L33,0) -> 0.08120742 | N15: =IFERROR(AVERAGE(C15:L15),0) -> 0.056401067 | O15: =IFERROR(MEDIAN(C15:L15),0) -> 0.061850773
B17: SalesExpenses%Sales | C17: =IFERROR('FS Analysis'!C15,0) -> 0.10925745 | D17: =IFERROR('FS Analysis'!D15,0) -> 0.089494772 | E17: =IFERROR('FS Analysis'!E15,0) -> 0.072013851 | F17: =IFERROR('FS Analysis'!F15,0) -> 0.099071358 | G17: =IFERROR('FS Analysis'!G15,0) -> 0.18431526 | H17: =IFERROR('FS Analysis'!H15,0) -> 0.1678327 | I17: =IFERROR('FS Analysis'!I15,0) -> 0.093464863 | J17: =IFERROR('FS Analysis'!J15,0) -> 0.0716377 | ... L17: =IFERROR('FS Analysis'!L15,0) -> 0.11371884 | N17: =IFERROR(AVERAGE(C17:L17),0) -> 0.10878436 | O17: =IFERROR(MEDIAN(C17:L17),0) -> 0.096268111
B18: Depreciation%Sales | C18: =IFERROR('FS Analysis'!C24,0) -> 0.032194149 | D18: =IFERROR('FS Analysis'!D24,0) -> 0.033575476 | E18: =IFERROR('FS Analysis'!E24,0) -> 0.035614717 | F18: =IFERROR('FS Analysis'!F24,0) -> 0.03810871 | G18: =IFERROR('FS Analysis'!G24,0) -> 0.044661632 | H18: =IFERROR('FS Analysis'!H24,0) -> 0.045479415 | I18: =IFERROR('FS Analysis'!I24,0) -> 0.038898501 | J18: =IFERROR('FS Analysis'!J24,0) -> 0.035926957 | ... L18: =IFERROR('FS Analysis'!L24,0) -> 0.038148475 | N18: =IFERROR(AVERAGE(C18:L18),0) -> 0.037657294 | O18: =IFERROR(MEDIAN(C18:L18),0) -> 0.037017833
B19: OperatingIncome%Sales | C19: =C13 -> 0.11919107 | D19: =D13 -> 0.11935485 | E19: =E13 -> 0.15541314 | F19: =F13 -> 0.13265947 | G19: =G13 -> 0.10182493 | H19: =H13 -> 0.12467282 | I19: =I13 -> 0.15947354 | J19: =J13 -> 0.16401557 | ... L19: =L13 -> 0.17689131 | N19: =IFERROR(AVERAGE(C19:L19),0) -> 0.14222218 | O19: =IFERROR(MEDIAN(C19:L19),0) -> 0.14403631
B21: Return on Capital Employed | C21: =IFERROR(('FS Analysis'!C17-'FS Analysis'!C23)/SUM('FS Analysis'!C46:C48),0) -> 0.13284654 | D21: =IFERROR(('FS Analysis'!D17-'FS Analysis'!D23)/SUM('FS Analysis'!D46:D48),0) -> 0.12730807 | E21: =IFERROR(('FS Analysis'!E17-'FS Analysis'!E23)/SUM('FS Analysis'!E46:E48),0) -> 0.15444189 | F21: =IFERROR(('FS Analysis'!F17-'FS Analysis'!F23)/SUM('FS Analysis'!F46:F48),0) -> 0.1253449 | G21: =IFERROR(('FS Analysis'!G17-'FS Analysis'!G23)/SUM('FS Analysis'!G46:G48),0) -> 0.062884319 | H21: =IFERROR(('FS Analysis'!H17-'FS Analysis'!H23)/SUM('FS Analysis'!H46:H48),0) -> 0.075776665 | I21: =IFERROR(('FS Analysis'!I17-'FS Analysis'!I23)/SUM('FS Analysis'!I46:I48),0) -> 0.11528957 | J21: =IFERROR(('FS Analysis'!J17-'FS Analysis'!J23)/SUM('FS Analysis'!J46:J48),0) -> 0.1338374 | ... L21: =IFERROR(('FS Analysis'!L17-'FS Analysis'!L23)/SUM('FS Analysis'!L46:L48),0) -> 0.13942901 | N21: =IFERROR(AVERAGE(C21:L21),0) -> 0.12013742 | O21: =IFERROR(MEDIAN(C21:L21),0) -> 0.13007731
B22: Retained Earnings% | C22: =IFERROR('FS Analysis'!C43,0) -> 0.79387822 | D22: =IFERROR('FS Analysis'!D43,0) -> 0.78166001 | E22: =IFERROR('FS Analysis'!E43,0) -> 0.89152361 | F22: =IFERROR('FS Analysis'!F43,0) -> 0.82603011 | G22: =IFERROR('FS Analysis'!G43,0) -> 0 | H22: =IFERROR('FS Analysis'!H43,0) -> 0.46399153 | I22: =IFERROR('FS Analysis'!I43,0) -> 0.80470769 | J22: =IFERROR('FS Analysis'!J43,0) -> 0.82398872 | ... L22: =IFERROR('FS Analysis'!L43,0) -> 0.78155943 | N22: =IFERROR(AVERAGE(C22:L22),0) -> 0.69586061 | O22: =IFERROR(MEDIAN(C22:L22),0) -> 0.79257248
B23: Return on Equity% | C23: =IFERROR('FS Analysis'!C32/SUM('FS Analysis'!C46:C47),0) -> 0.11884164 | D23: =IFERROR('FS Analysis'!D32/SUM('FS Analysis'!D46:D47),0) -> 0.12418844 | E23: =IFERROR('FS Analysis'!E32/SUM('FS Analysis'!E46:E47),0) -> 0.20422437 | F23: =IFERROR('FS Analysis'!F32/SUM('FS Analysis'!F46:F47),0) -> 0.13294164 | G23: =IFERROR('FS Analysis'!G32/SUM('FS Analysis'!G46:G47),0) -> 0.0031784387 | H23: =IFERROR('FS Analysis'!H32/SUM('FS Analysis'!H46:H47),0) -> 0.043588415 | I23: =IFERROR('FS Analysis'!I32/SUM('FS Analysis'!I46:I47),0) -> 0.13957877 | J23: =IFERROR('FS Analysis'!J32/SUM('FS Analysis'!J46:J47),0) -> 0.18240674 | ... L23: =IFERROR('FS Analysis'!L32/SUM('FS Analysis'!L46:L47),0) -> 0.16782569 | N23: =IFERROR(AVERAGE(C23:L23),0) -> 0.12870196 | O23: =IFERROR(MEDIAN(C23:L23),0) -> 0.1362602
B24: Self Sustained Growth Rate | C24: =IFERROR(C22*C23,0) -> 0.09434579 | D24: =IFERROR(D22*D23,0) -> 0.09707314 | E24: =IFERROR(E22*E23,0) -> 0.18207085 | F24: =IFERROR(F22*F23,0) -> 0.1098138 | G24: =IFERROR(G22*G23,0) -> 0 | H24: =IFERROR(H22*H23,0) -> 0.020224655 | I24: =IFERROR(I22*I23,0) -> 0.11232011 | J24: =IFERROR(J22*J23,0) -> 0.1503011 | ... L24: =IFERROR(L22*L23,0) -> 0.13116575 | N24: =IFERROR(AVERAGE(C24:L24),0) -> 0.10320247 | O24: =IFERROR(MEDIAN(C24:L24),0) -> 0.11106695
B25: Interest Coverage Ratio | C25: =IFERROR(('FS Analysis'!C17-'FS Analysis'!C23)/'FS Analysis'!C20,0) -> 2.6842995 | D25: =IFERROR(('FS Analysis'!D17-'FS Analysis'!D23)/'FS Analysis'!D20,0) -> 2.7405316 | E25: =IFERROR(('FS Analysis'!E17-'FS Analysis'!E23)/'FS Analysis'!E20,0) -> 3.5897384 | F25: =IFERROR(('FS Analysis'!F17-'FS Analysis'!F23)/'FS Analysis'!F20,0) -> 2.7666245 | G25: =IFERROR(('FS Analysis'!G17-'FS Analysis'!G23)/'FS Analysis'!G20,0) -> 1.2747997 | H25: =IFERROR(('FS Analysis'!H17-'FS Analysis'!H23)/'FS Analysis'!H20,0) -> 1.5175494 | I25: =IFERROR(('FS Analysis'!I17-'FS Analysis'!I23)/'FS Analysis'!I20,0) -> 2.8656191 | J25: =IFERROR(('FS Analysis'!J17-'FS Analysis'!J23)/'FS Analysis'!J20,0) -> 3.4118274 | ... L25: =IFERROR(('FS Analysis'!L17-'FS Analysis'!L23)/'FS Analysis'!L20,0) -> 3.1004955 | N25: =IFERROR(AVERAGE(C25:L25),0) -> 2.7085211 | O25: =IFERROR(MEDIAN(C25:L25),0) -> 2.8161218
B27: Debtor Turnover Ratio | C27: =IFERROR('FS Analysis'!C5/'FS Analysis'!C58,0) -> 13.036548 | D27: =IFERROR('FS Analysis'!D5/'FS Analysis'!D58,0) -> 11.636342 | E27: =IFERROR('FS Analysis'!E5/'FS Analysis'!E58,0) -> 10.847574 | F27: =IFERROR('FS Analysis'!F5/'FS Analysis'!F58,0) -> 12.067528 | G27: =IFERROR('FS Analysis'!G5/'FS Analysis'!G58,0) -> 10.880324 | H27: =IFERROR('FS Analysis'!H5/'FS Analysis'!H58,0) -> 12.36364 | I27: =IFERROR('FS Analysis'!I5/'FS Analysis'!I58,0) -> 14.146733 | J27: =IFERROR('FS Analysis'!J5/'FS Analysis'!J58,0) -> 17.255009 | ... L27: =IFERROR('FS Analysis'!L5/'FS Analysis'!L58,0) -> 19.229057 | N27: =IFERROR(AVERAGE(C27:L27),0) -> 14.010745 | O27: =IFERROR(MEDIAN(C27:L27),0) -> 12.700094
B28: Creditor Turnover Ratio | C28: =IFERROR('FS Analysis'!C5/'FS Analysis'!C49,0) -> 2.3844824 | D28: =IFERROR('FS Analysis'!D5/'FS Analysis'!D49,0) -> 2.3734485 | E28: =IFERROR('FS Analysis'!E5/'FS Analysis'!E49,0) -> 2.1075963 | F28: =IFERROR('FS Analysis'!F5/'FS Analysis'!F49,0) -> 2.0510563 | G28: =IFERROR('FS Analysis'!G5/'FS Analysis'!G49,0) -> 1.7267833 | H28: =IFERROR('FS Analysis'!H5/'FS Analysis'!H49,0) -> 1.7370214 | I28: =IFERROR('FS Analysis'!I5/'FS Analysis'!I49,0) -> 1.8919295 | J28: =IFERROR('FS Analysis'!J5/'FS Analysis'!J49,0) -> 2.1783273 | ... L28: =IFERROR('FS Analysis'!L5/'FS Analysis'!L49,0) -> 2.1060162 | N28: =IFERROR(AVERAGE(C28:L28),0) -> 2.0879125 | O28: =IFERROR(MEDIAN(C28:L28),0) -> 2.1068062
B29: Inventory Turnover | C29: =IFERROR('FS Analysis'!C5/'FS Analysis'!C59,0) -> 8.3194846 | D29: =IFERROR('FS Analysis'!D5/'FS Analysis'!D59,0) -> 9.4275215 | E29: =IFERROR('FS Analysis'!E5/'FS Analysis'!E59,0) -> 9.8648449 | F29: =IFERROR('FS Analysis'!F5/'FS Analysis'!F59,0) -> 8.5835497 | G29: =IFERROR('FS Analysis'!G5/'FS Analysis'!G59,0) -> 6.7839165 | H29: =IFERROR('FS Analysis'!H5/'FS Analysis'!H59,0) -> 7.7248687 | I29: =IFERROR('FS Analysis'!I5/'FS Analysis'!I59,0) -> 7.7761271 | J29: =IFERROR('FS Analysis'!J5/'FS Analysis'!J59,0) -> 7.1948244 | ... L29: =IFERROR('FS Analysis'!L5/'FS Analysis'!L59,0) -> 7.8309659 | N29: =IFERROR(AVERAGE(C29:L29),0) -> 8.0987263 | O29: =IFERROR(MEDIAN(C29:L29),0) -> 7.8035465
B30: Fixed Asset Turnover | C30: =IFERROR('FS Analysis'!C5/'FS Analysis'!C52,0) -> 3.684357 | D30: =IFERROR('FS Analysis'!D5/'FS Analysis'!D52,0) -> 3.9912816 | E30: =IFERROR('FS Analysis'!E5/'FS Analysis'!E52,0) -> 3.5174663 | F30: =IFERROR('FS Analysis'!F5/'FS Analysis'!F52,0) -> 3.6132084 | G30: =IFERROR('FS Analysis'!G5/'FS Analysis'!G52,0) -> 2.5390294 | H30: =IFERROR('FS Analysis'!H5/'FS Analysis'!H52,0) -> 3.4742232 | I30: =IFERROR('FS Analysis'!I5/'FS Analysis'!I52,0) -> 3.4656342 | J30: =IFERROR('FS Analysis'!J5/'FS Analysis'!J52,0) -> 4.4682623 | ... L30: =IFERROR('FS Analysis'!L5/'FS Analysis'!L52,0) -> 4.05308 | N30: =IFERROR(AVERAGE(C30:L30),0) -> 3.7750772 | O30: =IFERROR(MEDIAN(C30:L30),0) -> 3.6487827
B31: Capital Turnover Ratio | C31: =IFERROR('FS Analysis'!C5/SUM('FS Analysis'!C46:C47),0) -> 2.8627344 | D31: =IFERROR('FS Analysis'!D5/SUM('FS Analysis'!D46:D47),0) -> 2.8132861 | E31: =IFERROR('FS Analysis'!E5/SUM('FS Analysis'!E46:E47),0) -> 2.5042413 | F31: =IFERROR('FS Analysis'!F5/SUM('FS Analysis'!F46:F47),0) -> 2.6191033 | G31: =IFERROR('FS Analysis'!G5/SUM('FS Analysis'!G46:G47),0) -> 1.8859953 | H31: =IFERROR('FS Analysis'!H5/SUM('FS Analysis'!H46:H47),0) -> 1.7862999 | I31: =IFERROR('FS Analysis'!I5/SUM('FS Analysis'!I46:I47),0) -> 1.9135297 | J31: =IFERROR('FS Analysis'!J5/SUM('FS Analysis'!J46:J47),0) -> 2.1514566 | ... L31: =IFERROR('FS Analysis'!L5/SUM('FS Analysis'!L46:L47),0) -> 2.06663 | N31: =IFERROR(AVERAGE(C31:L31),0) -> 2.2704457 | O31: =IFERROR(MEDIAN(C31:L31),0) -> 2.1263184
B33: Debtor Days | C33: =IFERROR(365/C27,0) -> 27.99821 | D33: =IFERROR(365/D27,0) -> 31.367246 | E33: =IFERROR(365/E27,0) -> 33.648077 | F33: =IFERROR(365/F27,0) -> 30.24646 | G33: =IFERROR(365/G27,0) -> 33.546796 | H33: =IFERROR(365/H27,0) -> 29.522051 | I33: =IFERROR(365/I27,0) -> 25.80101 | J33: =IFERROR(365/J27,0) -> 21.153278 | ... L33: =IFERROR(365/L27,0) -> 18.98169 | N33: =IFERROR(AVERAGE(C33:L33),0) -> 27.184143 | O33: =IFERROR(MEDIAN(C33:L33),0) -> 28.76013
B34: Payable Days | C34: =IFERROR(365/C28,0) -> 153.07305 | D34: =IFERROR(365/D28,0) -> 153.78467 | E34: =IFERROR(365/E28,0) -> 173.18307 | F34: =IFERROR(365/F28,0) -> 177.95708 | G34: =IFERROR(365/G28,0) -> 211.37569 | H34: =IFERROR(365/H28,0) -> 210.12982 | I34: =IFERROR(365/I28,0) -> 192.92474 | J34: =IFERROR(365/J28,0) -> 167.55976 | ... L34: =IFERROR(365/L28,0) -> 173.31301 | N34: =IFERROR(AVERAGE(C34:L34),0) -> 177.04616 | O34: =IFERROR(MEDIAN(C34:L34),0) -> 173.24804
B35: Inventory Days | C35: =IFERROR(365/C29,0) -> 43.87291 | D35: =IFERROR(365/D29,0) -> 38.716433 | E35: =IFERROR(365/E29,0) -> 37.000075 | F35: =IFERROR(365/F29,0) -> 42.5232 | G35: =IFERROR(365/G29,0) -> 53.803729 | H35: =IFERROR(365/H29,0) -> 47.249994 | I35: =IFERROR(365/I29,0) -> 46.938533 | J35: =IFERROR(365/J29,0) -> 50.730911 | ... L35: =IFERROR(365/L29,0) -> 46.609831 | N35: =IFERROR(AVERAGE(C35:L35),0) -> 45.623484 | O35: =IFERROR(MEDIAN(C35:L35),0) -> 46.774182
B36: Cash Conversion Cycle (in days) | C36: =SUM(C33,C35)-C34 -> -81.201932 | D36: =SUM(D33,D35)-D34 -> -83.70099 | E36: =SUM(E33,E35)-E34 -> -102.53492 | F36: =SUM(F33,F35)-F34 -> -105.18742 | G36: =SUM(G33,G35)-G34 -> -124.02516 | H36: =SUM(H33,H35)-H34 -> -133.35778 | I36: =SUM(I33,I35)-I34 -> -120.1852 | J36: =SUM(J33,J35)-J34 -> -95.675569 | ... L36: =SUM(L33,L35)-L34 -> -107.72149 | N36: =IFERROR(AVERAGE(C36:L36),0) -> -104.23853 | O36: =IFERROR(MEDIAN(C36:L36),0) -> -103.86117
B38: CFO/Sales | C38: =IFERROR('FS Analysis'!C77/'FS Analysis'!C5,0) -> 0.031434011 | D38: =IFERROR('FS Analysis'!D77/'FS Analysis'!D5,0) -> 0.0021725364 | E38: =IFERROR('FS Analysis'!E77/'FS Analysis'!E5,0) -> 0.007405481 | F38: =IFERROR('FS Analysis'!F77/'FS Analysis'!F5,0) -> -0.041510426 | G38: =IFERROR('FS Analysis'!G77/'FS Analysis'!G5,0) -> -0.01932824 | H38: =IFERROR('FS Analysis'!H77/'FS Analysis'!H5,0) -> 0.24110844 | I38: =IFERROR('FS Analysis'!I77/'FS Analysis'!I5,0) -> 0.10256118 | J38: =IFERROR('FS Analysis'!J77/'FS Analysis'!J5,0) -> -0.058333344 | ... L38: =IFERROR('FS Analysis'!L77/'FS Analysis'!L5,0) -> 0.019948393 | N38: =IFERROR(AVERAGE(C38:L38),0) -> 0.024497723 | O38: =IFERROR(MEDIAN(C38:L38),0) -> 0.0047890087
B39: CFO/Total Assets | C39: =IFERROR('FS Analysis'!C77/'FS Analysis'!C63,0) -> 0.023875379 | D39: =IFERROR('FS Analysis'!D77/'FS Analysis'!D63,0) -> 0.0015987985 | E39: =IFERROR('FS Analysis'!E77/'FS Analysis'!E63,0) -> 0.0050011253 | F39: =IFERROR('FS Analysis'!F77/'FS Analysis'!F63,0) -> -0.026851788 | G39: =IFERROR('FS Analysis'!G77/'FS Analysis'!G63,0) -> -0.0087921435 | H39: =IFERROR('FS Analysis'!H77/'FS Analysis'!H63,0) -> 0.10856023 | I39: =IFERROR('FS Analysis'!I77/'FS Analysis'!I63,0) -> 0.053646273 | J39: =IFERROR('FS Analysis'!J77/'FS Analysis'!J63,0) -> -0.03462841 | ... L39: =IFERROR('FS Analysis'!L77/'FS Analysis'!L63,0) -> 0.011441488 | N39: =IFERROR(AVERAGE(C39:L39),0) -> 0.01098651 | O39: =IFERROR(MEDIAN(C39:L39),0) -> 0.0032999619
B40: CFO/Total Debt | C40: =IFERROR('FS Analysis'!C77/'FS Analysis'!C48,0) -> 0.057372609 | D40: =IFERROR('FS Analysis'!D77/'FS Analysis'!D48,0) -> 0.0037324215 | E40: =IFERROR('FS Analysis'!E77/'FS Analysis'!E48,0) -> 0.012200812 | F40: =IFERROR('FS Analysis'!F77/'FS Analysis'!F48,0) -> -0.061356448 | G40: =IFERROR('FS Analysis'!G77/'FS Analysis'!G48,0) -> -0.017748319 | H40: =IFERROR('FS Analysis'!H77/'FS Analysis'!H48,0) -> 0.2221276 | I40: =IFERROR('FS Analysis'!I77/'FS Analysis'!I48,0) -> 0.11916726 | J40: =IFERROR('FS Analysis'!J77/'FS Analysis'!J48,0) -> -0.076685545 | ... L40: =IFERROR('FS Analysis'!L77/'FS Analysis'!L48,0) -> 0.025418308 | N40: =IFERROR(AVERAGE(C40:L40),0) -> 0.023240962 | O40: =IFERROR(MEDIAN(C40:L40),0) -> 0.0079666166
